2025-04-13 23:14:54,085 [INFO] Starting homing procedure
2025-04-13 23:15:09,526 [INFO] Homing procedure complete and speed limits set
2025-04-13 23:15:09,529 [INFO] Homing complete
2025-04-13 23:15:44,862 [ERROR] Error in status_broadcast_loop
Traceback (most recent call last):
  File "/usr/lib/python3/dist-packages/gpiozero/devices.py", line 563, in _read
    return self._state_to_value(self.pin.state)
                                ^^^^^^^^^^^^^^
AttributeError: 'NoneType' object has no attribute 'state'

During handling of the above exception, another exception occurred:

Traceback (most recent call last):
  File "/usr/lib/python3/dist-packages/gpiozero/devices.py", line 584, in _check_open
    super()._check_open()
  File "/usr/lib/python3/dist-packages/gpiozero/devices.py", line 213, in _check_open
    raise DeviceClosed(
gpiozero.exc.DeviceClosed: OutputDevice is closed or uninitialized

During handling of the above exception, another exception occurred:

Traceback (most recent call last):
  File "/home/berke/Desktop/PurrfectSpray/Code/app.py", line 185, in status_broadcast_loop
    'laser': laser_pin.value,
             ^^^^^^^^^^^^^^^
  File "/usr/lib/python3/dist-packages/gpiozero/output_devices.py", line 121, in value
    return super().value
           ^^^^^^^^^^^^^
  File "/usr/lib/python3/dist-packages/gpiozero/devices.py", line 602, in value
    return self._read()
           ^^^^^^^^^^^^
  File "/usr/lib/python3/dist-packages/gpiozero/devices.py", line 565, in _read
    self._check_open()
  File "/usr/lib/python3/dist-packages/gpiozero/devices.py", line 587, in _check_open
    raise GPIODeviceClosed(str(e))
gpiozero.exc.GPIODeviceClosed: OutputDevice is closed or uninitialized
2025-04-13 23:21:19,456 [INFO] Starting homing procedure
2025-04-13 23:21:36,448 [INFO] Homing procedure complete and speed limits set
2025-04-13 23:21:36,448 [INFO] Homing complete
2025-04-13 23:22:05,412 [ERROR] Error in status_broadcast_loop
Traceback (most recent call last):
  File "/usr/lib/python3/dist-packages/gpiozero/devices.py", line 563, in _read
    return self._state_to_value(self.pin.state)
                                ^^^^^^^^^^^^^^
AttributeError: 'NoneType' object has no attribute 'state'

During handling of the above exception, another exception occurred:

Traceback (most recent call last):
  File "/usr/lib/python3/dist-packages/gpiozero/devices.py", line 584, in _check_open
    super()._check_open()
  File "/usr/lib/python3/dist-packages/gpiozero/devices.py", line 213, in _check_open
    raise DeviceClosed(
gpiozero.exc.DeviceClosed: OutputDevice is closed or uninitialized

During handling of the above exception, another exception occurred:

Traceback (most recent call last):
  File "/home/berke/Desktop/PurrfectSpray/Code/app.py", line 185, in status_broadcast_loop
    'laser': laser_pin.value,
             ^^^^^^^^^^^^^^^
  File "/usr/lib/python3/dist-packages/gpiozero/output_devices.py", line 121, in value
    return super().value
           ^^^^^^^^^^^^^
  File "/usr/lib/python3/dist-packages/gpiozero/devices.py", line 602, in value
    return self._read()
           ^^^^^^^^^^^^
  File "/usr/lib/python3/dist-packages/gpiozero/devices.py", line 565, in _read
    self._check_open()
  File "/usr/lib/python3/dist-packages/gpiozero/devices.py", line 587, in _check_open
    raise GPIODeviceClosed(str(e))
gpiozero.exc.GPIODeviceClosed: OutputDevice is closed or uninitialized
2025-04-13 23:25:24,122 [INFO] Starting homing procedure
2025-04-13 23:25:39,861 [INFO] Homing procedure complete and speed limits set
2025-04-13 23:25:39,861 [INFO] Homing complete
2025-04-13 23:28:35,708 [ERROR] Error in status_broadcast_loop
Traceback (most recent call last):
  File "/usr/lib/python3/dist-packages/gpiozero/devices.py", line 563, in _read
    return self._state_to_value(self.pin.state)
                                ^^^^^^^^^^^^^^
AttributeError: 'NoneType' object has no attribute 'state'

During handling of the above exception, another exception occurred:

Traceback (most recent call last):
  File "/usr/lib/python3/dist-packages/gpiozero/devices.py", line 584, in _check_open
    super()._check_open()
  File "/usr/lib/python3/dist-packages/gpiozero/devices.py", line 213, in _check_open
    raise DeviceClosed(
gpiozero.exc.DeviceClosed: OutputDevice is closed or uninitialized

During handling of the above exception, another exception occurred:

Traceback (most recent call last):
  File "/home/berke/Desktop/PurrfectSpray/Code/app.py", line 185, in status_broadcast_loop
    'laser': laser_pin.value,
             ^^^^^^^^^^^^^^^
  File "/usr/lib/python3/dist-packages/gpiozero/output_devices.py", line 121, in value
    return super().value
           ^^^^^^^^^^^^^
  File "/usr/lib/python3/dist-packages/gpiozero/devices.py", line 602, in value
    return self._read()
           ^^^^^^^^^^^^
  File "/usr/lib/python3/dist-packages/gpiozero/devices.py", line 565, in _read
    self._check_open()
  File "/usr/lib/python3/dist-packages/gpiozero/devices.py", line 587, in _check_open
    raise GPIODeviceClosed(str(e))
gpiozero.exc.GPIODeviceClosed: OutputDevice is closed or uninitialized
2025-04-13 23:28:39,732 [INFO] Starting homing procedure
2025-04-13 23:28:55,373 [INFO] Homing procedure complete and speed limits set
2025-04-13 23:28:55,373 [INFO] Homing complete
2025-04-14 20:12:58,802 [INFO] Starting homing procedure
2025-04-14 20:12:58,803 [INFO] Background threads started
2025-04-14 20:13:15,632 [INFO] Homing procedure complete and speed limits set
2025-04-14 20:13:15,633 [INFO] Homing complete
2025-04-14 20:13:17,936 [ERROR] Error in fan_loop
Traceback (most recent call last):
  File "/usr/lib/python3/dist-packages/gpiozero/output_devices.py", line 87, in _write
    self.pin.state = self._value_to_state(value)
    ^^^^^^^^^^^^^^
AttributeError: 'NoneType' object has no attribute 'state'

During handling of the above exception, another exception occurred:

Traceback (most recent call last):
  File "/usr/lib/python3/dist-packages/gpiozero/devices.py", line 584, in _check_open
    super()._check_open()
  File "/usr/lib/python3/dist-packages/gpiozero/devices.py", line 213, in _check_open
    raise DeviceClosed(
gpiozero.exc.DeviceClosed: OutputDevice is closed or uninitialized

During handling of the above exception, another exception occurred:

Traceback (most recent call last):
  File "/home/berke/Desktop/PurrfectSpray/Code/app.py", line 228, in fan_loop
    fan_pin.off()
  File "/usr/lib/python3/dist-packages/gpiozero/output_devices.py", line 102, in off
    self._write(False)
  File "/usr/lib/python3/dist-packages/gpiozero/output_devices.py", line 89, in _write
    self._check_open()
  File "/usr/lib/python3/dist-packages/gpiozero/devices.py", line 587, in _check_open
    raise GPIODeviceClosed(str(e))
gpiozero.exc.GPIODeviceClosed: OutputDevice is closed or uninitialized
2025-04-14 20:13:23,799 [INFO] Starting homing procedure
2025-04-14 20:13:23,800 [INFO] Background threads started
2025-04-14 20:13:38,781 [INFO] Homing procedure complete and speed limits set
2025-04-14 20:13:38,782 [INFO] Homing complete
2025-04-14 20:16:32,756 [ERROR] Error in status_broadcast_loop
Traceback (most recent call last):
  File "/usr/lib/python3/dist-packages/gpiozero/devices.py", line 563, in _read
    return self._state_to_value(self.pin.state)
                                ^^^^^^^^^^^^^^
AttributeError: 'NoneType' object has no attribute 'state'

During handling of the above exception, another exception occurred:

Traceback (most recent call last):
  File "/usr/lib/python3/dist-packages/gpiozero/devices.py", line 584, in _check_open
    super()._check_open()
  File "/usr/lib/python3/dist-packages/gpiozero/devices.py", line 213, in _check_open
    raise DeviceClosed(
gpiozero.exc.DeviceClosed: OutputDevice is closed or uninitialized

During handling of the above exception, another exception occurred:

Traceback (most recent call last):
  File "/home/berke/Desktop/PurrfectSpray/Code/app.py", line 241, in status_broadcast_loop
    'laser': laser_pin.value,
             ^^^^^^^^^^^^^^^
  File "/usr/lib/python3/dist-packages/gpiozero/output_devices.py", line 121, in value
    return super().value
           ^^^^^^^^^^^^^
  File "/usr/lib/python3/dist-packages/gpiozero/devices.py", line 602, in value
    return self._read()
           ^^^^^^^^^^^^
  File "/usr/lib/python3/dist-packages/gpiozero/devices.py", line 565, in _read
    self._check_open()
  File "/usr/lib/python3/dist-packages/gpiozero/devices.py", line 587, in _check_open
    raise GPIODeviceClosed(str(e))
gpiozero.exc.GPIODeviceClosed: OutputDevice is closed or uninitialized
2025-04-14 20:16:32,937 [ERROR] Error in fan_loop
Traceback (most recent call last):
  File "/usr/lib/python3/dist-packages/gpiozero/output_devices.py", line 87, in _write
    self.pin.state = self._value_to_state(value)
    ^^^^^^^^^^^^^^
AttributeError: 'NoneType' object has no attribute 'state'

During handling of the above exception, another exception occurred:

Traceback (most recent call last):
  File "/usr/lib/python3/dist-packages/gpiozero/devices.py", line 584, in _check_open
    super()._check_open()
  File "/usr/lib/python3/dist-packages/gpiozero/devices.py", line 213, in _check_open
    raise DeviceClosed(
gpiozero.exc.DeviceClosed: OutputDevice is closed or uninitialized

During handling of the above exception, another exception occurred:

Traceback (most recent call last):
  File "/home/berke/Desktop/PurrfectSpray/Code/app.py", line 228, in fan_loop
    fan_pin.off()
  File "/usr/lib/python3/dist-packages/gpiozero/output_devices.py", line 102, in off
    self._write(False)
  File "/usr/lib/python3/dist-packages/gpiozero/output_devices.py", line 89, in _write
    self._check_open()
  File "/usr/lib/python3/dist-packages/gpiozero/devices.py", line 587, in _check_open
    raise GPIODeviceClosed(str(e))
gpiozero.exc.GPIODeviceClosed: OutputDevice is closed or uninitialized
2025-04-14 20:16:38,853 [INFO] Starting homing procedure
2025-04-14 20:16:38,858 [INFO] Background threads started
2025-04-14 20:16:55,371 [INFO] Homing procedure complete and speed limits set
2025-04-14 20:16:55,371 [INFO] Homing complete
2025-04-14 20:23:27,940 [INFO] Starting homing procedure
2025-04-14 20:23:27,948 [INFO] Background threads started
2025-04-14 20:23:44,984 [INFO] Homing procedure complete and speed limits set
2025-04-14 20:23:44,984 [INFO] Homing complete
2025-04-14 20:24:08,193 [ERROR] Error in status_broadcast_loop
Traceback (most recent call last):
  File "/usr/lib/python3/dist-packages/gpiozero/devices.py", line 563, in _read
    return self._state_to_value(self.pin.state)
                                ^^^^^^^^^^^^^^
AttributeError: 'NoneType' object has no attribute 'state'

During handling of the above exception, another exception occurred:

Traceback (most recent call last):
  File "/usr/lib/python3/dist-packages/gpiozero/devices.py", line 584, in _check_open
    super()._check_open()
  File "/usr/lib/python3/dist-packages/gpiozero/devices.py", line 213, in _check_open
    raise DeviceClosed(
gpiozero.exc.DeviceClosed: OutputDevice is closed or uninitialized

During handling of the above exception, another exception occurred:

Traceback (most recent call last):
  File "/home/berke/Desktop/PurrfectSpray/Code/app.py", line 241, in status_broadcast_loop
    'laser': laser_pin.value,
             ^^^^^^^^^^^^^^^
  File "/usr/lib/python3/dist-packages/gpiozero/output_devices.py", line 121, in value
    return super().value
           ^^^^^^^^^^^^^
  File "/usr/lib/python3/dist-packages/gpiozero/devices.py", line 602, in value
    return self._read()
           ^^^^^^^^^^^^
  File "/usr/lib/python3/dist-packages/gpiozero/devices.py", line 565, in _read
    self._check_open()
  File "/usr/lib/python3/dist-packages/gpiozero/devices.py", line 587, in _check_open
    raise GPIODeviceClosed(str(e))
gpiozero.exc.GPIODeviceClosed: OutputDevice is closed or uninitialized
2025-04-14 20:24:08,224 [ERROR] Error in fan_loop
Traceback (most recent call last):
  File "/usr/lib/python3/dist-packages/gpiozero/output_devices.py", line 87, in _write
    self.pin.state = self._value_to_state(value)
    ^^^^^^^^^^^^^^
AttributeError: 'NoneType' object has no attribute 'state'

During handling of the above exception, another exception occurred:

Traceback (most recent call last):
  File "/usr/lib/python3/dist-packages/gpiozero/devices.py", line 584, in _check_open
    super()._check_open()
  File "/usr/lib/python3/dist-packages/gpiozero/devices.py", line 213, in _check_open
    raise DeviceClosed(
gpiozero.exc.DeviceClosed: OutputDevice is closed or uninitialized

During handling of the above exception, another exception occurred:

Traceback (most recent call last):
  File "/home/berke/Desktop/PurrfectSpray/Code/app.py", line 228, in fan_loop
    fan_pin.off()
  File "/usr/lib/python3/dist-packages/gpiozero/output_devices.py", line 102, in off
    self._write(False)
  File "/usr/lib/python3/dist-packages/gpiozero/output_devices.py", line 89, in _write
    self._check_open()
  File "/usr/lib/python3/dist-packages/gpiozero/devices.py", line 587, in _check_open
    raise GPIODeviceClosed(str(e))
gpiozero.exc.GPIODeviceClosed: OutputDevice is closed or uninitialized
2025-04-14 20:32:43,449 [INFO] Starting homing procedure
2025-04-14 20:32:43,454 [INFO] Background threads started
2025-04-14 20:32:59,213 [INFO] Homing procedure complete and speed limits set
2025-04-14 20:32:59,213 [INFO] Homing complete
2025-04-14 20:40:56,856 [ERROR] Error in fan_loop
Traceback (most recent call last):
  File "/usr/lib/python3/dist-packages/gpiozero/output_devices.py", line 87, in _write
    self.pin.state = self._value_to_state(value)
    ^^^^^^^^^^^^^^
AttributeError: 'NoneType' object has no attribute 'state'

During handling of the above exception, another exception occurred:

Traceback (most recent call last):
  File "/usr/lib/python3/dist-packages/gpiozero/devices.py", line 584, in _check_open
    super()._check_open()
  File "/usr/lib/python3/dist-packages/gpiozero/devices.py", line 213, in _check_open
    raise DeviceClosed(
gpiozero.exc.DeviceClosed: OutputDevice is closed or uninitialized

During handling of the above exception, another exception occurred:

Traceback (most recent call last):
  File "/home/berke/Desktop/PurrfectSpray/Code/app.py", line 228, in fan_loop
    fan_pin.off()
  File "/usr/lib/python3/dist-packages/gpiozero/output_devices.py", line 102, in off
    self._write(False)
  File "/usr/lib/python3/dist-packages/gpiozero/output_devices.py", line 89, in _write
    self._check_open()
  File "/usr/lib/python3/dist-packages/gpiozero/devices.py", line 587, in _check_open
    raise GPIODeviceClosed(str(e))
gpiozero.exc.GPIODeviceClosed: OutputDevice is closed or uninitialized
2025-04-14 20:40:57,034 [ERROR] Error in status_broadcast_loop
Traceback (most recent call last):
  File "/usr/lib/python3/dist-packages/gpiozero/devices.py", line 563, in _read
    return self._state_to_value(self.pin.state)
                                ^^^^^^^^^^^^^^
AttributeError: 'NoneType' object has no attribute 'state'

During handling of the above exception, another exception occurred:

Traceback (most recent call last):
  File "/usr/lib/python3/dist-packages/gpiozero/devices.py", line 584, in _check_open
    super()._check_open()
  File "/usr/lib/python3/dist-packages/gpiozero/devices.py", line 213, in _check_open
    raise DeviceClosed(
gpiozero.exc.DeviceClosed: OutputDevice is closed or uninitialized

During handling of the above exception, another exception occurred:

Traceback (most recent call last):
  File "/home/berke/Desktop/PurrfectSpray/Code/app.py", line 241, in status_broadcast_loop
    'laser': laser_pin.value,
             ^^^^^^^^^^^^^^^
  File "/usr/lib/python3/dist-packages/gpiozero/output_devices.py", line 121, in value
    return super().value
           ^^^^^^^^^^^^^
  File "/usr/lib/python3/dist-packages/gpiozero/devices.py", line 602, in value
    return self._read()
           ^^^^^^^^^^^^
  File "/usr/lib/python3/dist-packages/gpiozero/devices.py", line 565, in _read
    self._check_open()
  File "/usr/lib/python3/dist-packages/gpiozero/devices.py", line 587, in _check_open
    raise GPIODeviceClosed(str(e))
gpiozero.exc.GPIODeviceClosed: OutputDevice is closed or uninitialized
2025-04-14 20:41:02,501 [INFO] Starting homing procedure
2025-04-14 20:41:02,503 [INFO] Background threads started
2025-04-14 20:41:17,384 [INFO] Homing procedure complete and speed limits set
2025-04-14 20:41:17,384 [INFO] Homing complete
2025-04-14 20:57:44,361 [ERROR] Error in status_broadcast_loop
Traceback (most recent call last):
  File "/usr/lib/python3/dist-packages/gpiozero/devices.py", line 563, in _read
    return self._state_to_value(self.pin.state)
                                ^^^^^^^^^^^^^^
AttributeError: 'NoneType' object has no attribute 'state'

During handling of the above exception, another exception occurred:

Traceback (most recent call last):
  File "/usr/lib/python3/dist-packages/gpiozero/devices.py", line 584, in _check_open
    super()._check_open()
  File "/usr/lib/python3/dist-packages/gpiozero/devices.py", line 213, in _check_open
    raise DeviceClosed(
gpiozero.exc.DeviceClosed: OutputDevice is closed or uninitialized

During handling of the above exception, another exception occurred:

Traceback (most recent call last):
  File "/home/berke/Desktop/PurrfectSpray/Code/app.py", line 241, in status_broadcast_loop
    'laser': laser_pin.value,
             ^^^^^^^^^^^^^^^
  File "/usr/lib/python3/dist-packages/gpiozero/output_devices.py", line 121, in value
    return super().value
           ^^^^^^^^^^^^^
  File "/usr/lib/python3/dist-packages/gpiozero/devices.py", line 602, in value
    return self._read()
           ^^^^^^^^^^^^
  File "/usr/lib/python3/dist-packages/gpiozero/devices.py", line 565, in _read
    self._check_open()
  File "/usr/lib/python3/dist-packages/gpiozero/devices.py", line 587, in _check_open
    raise GPIODeviceClosed(str(e))
gpiozero.exc.GPIODeviceClosed: OutputDevice is closed or uninitialized
2025-04-14 20:57:49,696 [INFO] Starting homing procedure
2025-04-14 20:57:49,703 [INFO] Background threads started
2025-04-14 20:58:06,478 [INFO] Homing procedure complete and speed limits set
2025-04-14 20:58:06,478 [INFO] Homing complete
2025-04-14 21:01:08,487 [ERROR] Error in status_broadcast_loop
Traceback (most recent call last):
  File "/usr/lib/python3/dist-packages/gpiozero/devices.py", line 563, in _read
    return self._state_to_value(self.pin.state)
                                ^^^^^^^^^^^^^^
AttributeError: 'NoneType' object has no attribute 'state'

During handling of the above exception, another exception occurred:

Traceback (most recent call last):
  File "/usr/lib/python3/dist-packages/gpiozero/devices.py", line 584, in _check_open
    super()._check_open()
  File "/usr/lib/python3/dist-packages/gpiozero/devices.py", line 213, in _check_open
    raise DeviceClosed(
gpiozero.exc.DeviceClosed: OutputDevice is closed or uninitialized

During handling of the above exception, another exception occurred:

Traceback (most recent call last):
  File "/home/berke/Desktop/PurrfectSpray/Code/app.py", line 241, in status_broadcast_loop
    'laser': laser_pin.value,
             ^^^^^^^^^^^^^^^
  File "/usr/lib/python3/dist-packages/gpiozero/output_devices.py", line 121, in value
    return super().value
           ^^^^^^^^^^^^^
  File "/usr/lib/python3/dist-packages/gpiozero/devices.py", line 602, in value
    return self._read()
           ^^^^^^^^^^^^
  File "/usr/lib/python3/dist-packages/gpiozero/devices.py", line 565, in _read
    self._check_open()
  File "/usr/lib/python3/dist-packages/gpiozero/devices.py", line 587, in _check_open
    raise GPIODeviceClosed(str(e))
gpiozero.exc.GPIODeviceClosed: OutputDevice is closed or uninitialized
2025-04-14 21:01:13,827 [INFO] Starting homing procedure
2025-04-14 21:01:13,830 [INFO] Background threads started
2025-04-14 21:01:28,696 [ERROR] Error during homing_procedure
Traceback (most recent call last):
  File "/usr/lib/python3/dist-packages/gpiozero/devices.py", line 563, in _read
    return self._state_to_value(self.pin.state)
                                ^^^^^^^^^^^^^^
AttributeError: 'NoneType' object has no attribute 'state'

During handling of the above exception, another exception occurred:

Traceback (most recent call last):
  File "/usr/lib/python3/dist-packages/gpiozero/devices.py", line 584, in _check_open
    super()._check_open()
  File "/usr/lib/python3/dist-packages/gpiozero/devices.py", line 213, in _check_open
    raise DeviceClosed(
gpiozero.exc.DeviceClosed: DigitalInputDevice is closed or uninitialized

During handling of the above exception, another exception occurred:

Traceback (most recent call last):
  File "/home/berke/Desktop/PurrfectSpray/Code/motors.py", line 77, in homing_procedure
    home_motor(Motor2, hall_sensor_2, 2)
  File "/home/berke/Desktop/PurrfectSpray/Code/motors.py", line 54, in home_motor
    while read_sensor():
          ^^^^^^^^^^^^^
  File "/home/berke/Desktop/PurrfectSpray/Code/motors.py", line 36, in read_sensor
    return not hall_sensor.value
               ^^^^^^^^^^^^^^^^^
  File "/usr/lib/python3/dist-packages/gpiozero/devices.py", line 602, in value
    return self._read()
           ^^^^^^^^^^^^
  File "/usr/lib/python3/dist-packages/gpiozero/devices.py", line 565, in _read
    self._check_open()
  File "/usr/lib/python3/dist-packages/gpiozero/devices.py", line 587, in _check_open
    raise GPIODeviceClosed(str(e))
gpiozero.exc.GPIODeviceClosed: DigitalInputDevice is closed or uninitialized
2025-04-14 21:01:28,800 [INFO] Homing complete
2025-04-14 21:01:28,800 [ERROR] Error in motor_loop
Traceback (most recent call last):
  File "/usr/lib/python3/dist-packages/gpiozero/output_devices.py", line 87, in _write
    self.pin.state = self._value_to_state(value)
    ^^^^^^^^^^^^^^
AttributeError: 'NoneType' object has no attribute 'state'

During handling of the above exception, another exception occurred:

Traceback (most recent call last):
  File "/usr/lib/python3/dist-packages/gpiozero/devices.py", line 584, in _check_open
    super()._check_open()
  File "/usr/lib/python3/dist-packages/gpiozero/devices.py", line 213, in _check_open
    raise DeviceClosed(
gpiozero.exc.DeviceClosed: DigitalOutputDevice is closed or uninitialized

During handling of the above exception, another exception occurred:

Traceback (most recent call last):
  File "/home/berke/Desktop/PurrfectSpray/Code/app.py", line 210, in motor_loop
    Motor2.run()
  File "/home/berke/Desktop/PurrfectSpray/Code/AccelStepper.py", line 134, in run
    if self.run_speed():
       ^^^^^^^^^^^^^^^^
  File "/home/berke/Desktop/PurrfectSpray/Code/AccelStepper.py", line 75, in run_speed
    self.step(self._currentPos)
  File "/home/berke/Desktop/PurrfectSpray/Code/AccelStepper.py", line 180, in step
    self.step1(step)
  File "/home/berke/Desktop/PurrfectSpray/Code/AccelStepper.py", line 212, in step1
    self.set_output_pins(0b10 if self._direction else 0b00)
  File "/home/berke/Desktop/PurrfectSpray/Code/AccelStepper.py", line 203, in set_output_pins
    self._pins[i].off() if not self._pinInverted[i] else self._pins[i].on()
    ^^^^^^^^^^^^^^^^^^^
  File "/usr/lib/python3/dist-packages/gpiozero/output_devices.py", line 214, in off
    self._write(False)
  File "/usr/lib/python3/dist-packages/gpiozero/output_devices.py", line 89, in _write
    self._check_open()
  File "/usr/lib/python3/dist-packages/gpiozero/devices.py", line 587, in _check_open
    raise GPIODeviceClosed(str(e))
gpiozero.exc.GPIODeviceClosed: DigitalOutputDevice is closed or uninitialized
2025-04-14 21:01:28,891 [ERROR] Error in fan_loop
Traceback (most recent call last):
  File "/usr/lib/python3/dist-packages/gpiozero/output_devices.py", line 87, in _write
    self.pin.state = self._value_to_state(value)
    ^^^^^^^^^^^^^^
AttributeError: 'NoneType' object has no attribute 'state'

During handling of the above exception, another exception occurred:

Traceback (most recent call last):
  File "/usr/lib/python3/dist-packages/gpiozero/devices.py", line 584, in _check_open
    super()._check_open()
  File "/usr/lib/python3/dist-packages/gpiozero/devices.py", line 213, in _check_open
    raise DeviceClosed(
gpiozero.exc.DeviceClosed: OutputDevice is closed or uninitialized

During handling of the above exception, another exception occurred:

Traceback (most recent call last):
  File "/home/berke/Desktop/PurrfectSpray/Code/app.py", line 228, in fan_loop
    fan_pin.off()
  File "/usr/lib/python3/dist-packages/gpiozero/output_devices.py", line 102, in off
    self._write(False)
  File "/usr/lib/python3/dist-packages/gpiozero/output_devices.py", line 89, in _write
    self._check_open()
  File "/usr/lib/python3/dist-packages/gpiozero/devices.py", line 587, in _check_open
    raise GPIODeviceClosed(str(e))
gpiozero.exc.GPIODeviceClosed: OutputDevice is closed or uninitialized
2025-04-14 21:01:28,962 [ERROR] Error in status_broadcast_loop
Traceback (most recent call last):
  File "/usr/lib/python3/dist-packages/gpiozero/devices.py", line 563, in _read
    return self._state_to_value(self.pin.state)
                                ^^^^^^^^^^^^^^
AttributeError: 'NoneType' object has no attribute 'state'

During handling of the above exception, another exception occurred:

Traceback (most recent call last):
  File "/usr/lib/python3/dist-packages/gpiozero/devices.py", line 584, in _check_open
    super()._check_open()
  File "/usr/lib/python3/dist-packages/gpiozero/devices.py", line 213, in _check_open
    raise DeviceClosed(
gpiozero.exc.DeviceClosed: OutputDevice is closed or uninitialized

During handling of the above exception, another exception occurred:

Traceback (most recent call last):
  File "/home/berke/Desktop/PurrfectSpray/Code/app.py", line 241, in status_broadcast_loop
    'laser': laser_pin.value,
             ^^^^^^^^^^^^^^^
  File "/usr/lib/python3/dist-packages/gpiozero/output_devices.py", line 121, in value
    return super().value
           ^^^^^^^^^^^^^
  File "/usr/lib/python3/dist-packages/gpiozero/devices.py", line 602, in value
    return self._read()
           ^^^^^^^^^^^^
  File "/usr/lib/python3/dist-packages/gpiozero/devices.py", line 565, in _read
    self._check_open()
  File "/usr/lib/python3/dist-packages/gpiozero/devices.py", line 587, in _check_open
    raise GPIODeviceClosed(str(e))
gpiozero.exc.GPIODeviceClosed: OutputDevice is closed or uninitialized
2025-04-14 21:01:35,448 [INFO] Starting homing procedure
2025-04-14 21:01:35,454 [INFO] Background threads started
2025-04-14 21:01:49,545 [INFO] Homing procedure complete and speed limits set
2025-04-14 21:01:49,545 [INFO] Homing complete
2025-04-14 21:02:13,920 [ERROR] Error in fan_loop
Traceback (most recent call last):
  File "/usr/lib/python3/dist-packages/gpiozero/output_devices.py", line 87, in _write
    self.pin.state = self._value_to_state(value)
    ^^^^^^^^^^^^^^
AttributeError: 'NoneType' object has no attribute 'state'

During handling of the above exception, another exception occurred:

Traceback (most recent call last):
  File "/usr/lib/python3/dist-packages/gpiozero/devices.py", line 584, in _check_open
    super()._check_open()
  File "/usr/lib/python3/dist-packages/gpiozero/devices.py", line 213, in _check_open
    raise DeviceClosed(
gpiozero.exc.DeviceClosed: OutputDevice is closed or uninitialized

During handling of the above exception, another exception occurred:

Traceback (most recent call last):
  File "/home/berke/Desktop/PurrfectSpray/Code/app.py", line 228, in fan_loop
    fan_pin.off()
  File "/usr/lib/python3/dist-packages/gpiozero/output_devices.py", line 102, in off
    self._write(False)
  File "/usr/lib/python3/dist-packages/gpiozero/output_devices.py", line 89, in _write
    self._check_open()
  File "/usr/lib/python3/dist-packages/gpiozero/devices.py", line 587, in _check_open
    raise GPIODeviceClosed(str(e))
gpiozero.exc.GPIODeviceClosed: OutputDevice is closed or uninitialized
2025-04-14 21:02:14,091 [ERROR] Error in status_broadcast_loop
Traceback (most recent call last):
  File "/usr/lib/python3/dist-packages/gpiozero/devices.py", line 563, in _read
    return self._state_to_value(self.pin.state)
                                ^^^^^^^^^^^^^^
AttributeError: 'NoneType' object has no attribute 'state'

During handling of the above exception, another exception occurred:

Traceback (most recent call last):
  File "/usr/lib/python3/dist-packages/gpiozero/devices.py", line 584, in _check_open
    super()._check_open()
  File "/usr/lib/python3/dist-packages/gpiozero/devices.py", line 213, in _check_open
    raise DeviceClosed(
gpiozero.exc.DeviceClosed: OutputDevice is closed or uninitialized

During handling of the above exception, another exception occurred:

Traceback (most recent call last):
  File "/home/berke/Desktop/PurrfectSpray/Code/app.py", line 241, in status_broadcast_loop
    'laser': laser_pin.value,
             ^^^^^^^^^^^^^^^
  File "/usr/lib/python3/dist-packages/gpiozero/output_devices.py", line 121, in value
    return super().value
           ^^^^^^^^^^^^^
  File "/usr/lib/python3/dist-packages/gpiozero/devices.py", line 602, in value
    return self._read()
           ^^^^^^^^^^^^
  File "/usr/lib/python3/dist-packages/gpiozero/devices.py", line 565, in _read
    self._check_open()
  File "/usr/lib/python3/dist-packages/gpiozero/devices.py", line 587, in _check_open
    raise GPIODeviceClosed(str(e))
gpiozero.exc.GPIODeviceClosed: OutputDevice is closed or uninitialized
2025-04-14 21:02:21,269 [INFO] Starting homing procedure
2025-04-14 21:02:21,281 [INFO] Background threads started
2025-04-14 21:02:35,996 [INFO] Homing procedure complete and speed limits set
2025-04-14 21:02:35,997 [INFO] Homing complete
2025-04-14 21:03:11,992 [ERROR] Error in status_broadcast_loop
Traceback (most recent call last):
  File "/usr/lib/python3/dist-packages/gpiozero/devices.py", line 563, in _read
    return self._state_to_value(self.pin.state)
                                ^^^^^^^^^^^^^^
AttributeError: 'NoneType' object has no attribute 'state'

During handling of the above exception, another exception occurred:

Traceback (most recent call last):
  File "/usr/lib/python3/dist-packages/gpiozero/devices.py", line 584, in _check_open
    super()._check_open()
  File "/usr/lib/python3/dist-packages/gpiozero/devices.py", line 213, in _check_open
    raise DeviceClosed(
gpiozero.exc.DeviceClosed: OutputDevice is closed or uninitialized

During handling of the above exception, another exception occurred:

Traceback (most recent call last):
  File "/home/berke/Desktop/PurrfectSpray/Code/app.py", line 241, in status_broadcast_loop
    'laser': laser_pin.value,
             ^^^^^^^^^^^^^^^
  File "/usr/lib/python3/dist-packages/gpiozero/output_devices.py", line 121, in value
    return super().value
           ^^^^^^^^^^^^^
  File "/usr/lib/python3/dist-packages/gpiozero/devices.py", line 602, in value
    return self._read()
           ^^^^^^^^^^^^
  File "/usr/lib/python3/dist-packages/gpiozero/devices.py", line 565, in _read
    self._check_open()
  File "/usr/lib/python3/dist-packages/gpiozero/devices.py", line 587, in _check_open
    raise GPIODeviceClosed(str(e))
gpiozero.exc.GPIODeviceClosed: OutputDevice is closed or uninitialized
2025-04-14 21:03:36,962 [INFO] Starting homing procedure
2025-04-14 21:03:36,966 [INFO] Background threads started
2025-04-14 21:03:54,141 [INFO] Homing procedure complete and speed limits set
2025-04-14 21:03:54,141 [INFO] Homing complete
2025-04-14 21:08:41,996 [ERROR] Error in status_broadcast_loop
Traceback (most recent call last):
  File "/usr/lib/python3/dist-packages/gpiozero/devices.py", line 563, in _read
    return self._state_to_value(self.pin.state)
                                ^^^^^^^^^^^^^^
AttributeError: 'NoneType' object has no attribute 'state'

During handling of the above exception, another exception occurred:

Traceback (most recent call last):
  File "/usr/lib/python3/dist-packages/gpiozero/devices.py", line 584, in _check_open
    super()._check_open()
  File "/usr/lib/python3/dist-packages/gpiozero/devices.py", line 213, in _check_open
    raise DeviceClosed(
gpiozero.exc.DeviceClosed: OutputDevice is closed or uninitialized

During handling of the above exception, another exception occurred:

Traceback (most recent call last):
  File "/home/berke/Desktop/PurrfectSpray/Code/app.py", line 241, in status_broadcast_loop
    'laser': laser_pin.value,
             ^^^^^^^^^^^^^^^
  File "/usr/lib/python3/dist-packages/gpiozero/output_devices.py", line 121, in value
    return super().value
           ^^^^^^^^^^^^^
  File "/usr/lib/python3/dist-packages/gpiozero/devices.py", line 602, in value
    return self._read()
           ^^^^^^^^^^^^
  File "/usr/lib/python3/dist-packages/gpiozero/devices.py", line 565, in _read
    self._check_open()
  File "/usr/lib/python3/dist-packages/gpiozero/devices.py", line 587, in _check_open
    raise GPIODeviceClosed(str(e))
gpiozero.exc.GPIODeviceClosed: OutputDevice is closed or uninitialized
2025-04-14 21:08:50,450 [INFO] Starting homing procedure
2025-04-14 21:08:50,453 [INFO] Background threads started
2025-04-14 21:09:05,191 [INFO] Homing procedure complete and speed limits set
2025-04-14 21:09:05,194 [INFO] Homing complete
2025-04-14 21:13:24,399 [ERROR] Error in fan_loop
Traceback (most recent call last):
  File "/usr/lib/python3/dist-packages/gpiozero/output_devices.py", line 87, in _write
    self.pin.state = self._value_to_state(value)
    ^^^^^^^^^^^^^^
AttributeError: 'NoneType' object has no attribute 'state'

During handling of the above exception, another exception occurred:

Traceback (most recent call last):
  File "/usr/lib/python3/dist-packages/gpiozero/devices.py", line 584, in _check_open
    super()._check_open()
  File "/usr/lib/python3/dist-packages/gpiozero/devices.py", line 213, in _check_open
    raise DeviceClosed(
gpiozero.exc.DeviceClosed: OutputDevice is closed or uninitialized

During handling of the above exception, another exception occurred:

Traceback (most recent call last):
  File "/home/berke/Desktop/PurrfectSpray/Code/app.py", line 228, in fan_loop
    fan_pin.off()
  File "/usr/lib/python3/dist-packages/gpiozero/output_devices.py", line 102, in off
    self._write(False)
  File "/usr/lib/python3/dist-packages/gpiozero/output_devices.py", line 89, in _write
    self._check_open()
  File "/usr/lib/python3/dist-packages/gpiozero/devices.py", line 587, in _check_open
    raise GPIODeviceClosed(str(e))
gpiozero.exc.GPIODeviceClosed: OutputDevice is closed or uninitialized
2025-04-14 21:13:34,714 [INFO] Starting homing procedure
2025-04-14 21:13:34,717 [INFO] Background threads started
2025-04-14 21:13:50,471 [INFO] Homing procedure complete and speed limits set
2025-04-14 21:13:50,473 [INFO] Homing complete
2025-04-14 21:18:09,091 [ERROR] Error in status_broadcast_loop
Traceback (most recent call last):
  File "/usr/lib/python3/dist-packages/gpiozero/devices.py", line 563, in _read
    return self._state_to_value(self.pin.state)
                                ^^^^^^^^^^^^^^
AttributeError: 'NoneType' object has no attribute 'state'

During handling of the above exception, another exception occurred:

Traceback (most recent call last):
  File "/usr/lib/python3/dist-packages/gpiozero/devices.py", line 584, in _check_open
    super()._check_open()
  File "/usr/lib/python3/dist-packages/gpiozero/devices.py", line 213, in _check_open
    raise DeviceClosed(
gpiozero.exc.DeviceClosed: OutputDevice is closed or uninitialized

During handling of the above exception, another exception occurred:

Traceback (most recent call last):
  File "/home/berke/Desktop/PurrfectSpray/Code/app.py", line 241, in status_broadcast_loop
    'laser': laser_pin.value,
             ^^^^^^^^^^^^^^^
  File "/usr/lib/python3/dist-packages/gpiozero/output_devices.py", line 121, in value
    return super().value
           ^^^^^^^^^^^^^
  File "/usr/lib/python3/dist-packages/gpiozero/devices.py", line 602, in value
    return self._read()
           ^^^^^^^^^^^^
  File "/usr/lib/python3/dist-packages/gpiozero/devices.py", line 565, in _read
    self._check_open()
  File "/usr/lib/python3/dist-packages/gpiozero/devices.py", line 587, in _check_open
    raise GPIODeviceClosed(str(e))
gpiozero.exc.GPIODeviceClosed: OutputDevice is closed or uninitialized
2025-04-14 21:18:21,306 [INFO] Starting homing procedure
2025-04-14 21:18:21,312 [INFO] Background threads started
2025-04-14 21:18:37,046 [INFO] Homing procedure complete and speed limits set
2025-04-14 21:18:37,046 [INFO] Homing complete
2025-04-14 21:21:03,248 [INFO] Starting homing procedure
2025-04-14 21:21:03,252 [INFO] Background threads started
2025-04-14 21:21:19,016 [INFO] Homing procedure complete and speed limits set
2025-04-14 21:21:19,017 [INFO] Homing complete
2025-04-14 21:23:13,126 [ERROR] Error in status_broadcast_loop
Traceback (most recent call last):
  File "/usr/lib/python3/dist-packages/gpiozero/devices.py", line 563, in _read
    return self._state_to_value(self.pin.state)
                                ^^^^^^^^^^^^^^
AttributeError: 'NoneType' object has no attribute 'state'

During handling of the above exception, another exception occurred:

Traceback (most recent call last):
  File "/usr/lib/python3/dist-packages/gpiozero/devices.py", line 584, in _check_open
    super()._check_open()
  File "/usr/lib/python3/dist-packages/gpiozero/devices.py", line 213, in _check_open
    raise DeviceClosed(
gpiozero.exc.DeviceClosed: OutputDevice is closed or uninitialized

During handling of the above exception, another exception occurred:

Traceback (most recent call last):
  File "/home/berke/Desktop/PurrfectSpray/Code/app.py", line 241, in status_broadcast_loop
    'laser': laser_pin.value,
             ^^^^^^^^^^^^^^^
  File "/usr/lib/python3/dist-packages/gpiozero/output_devices.py", line 121, in value
    return super().value
           ^^^^^^^^^^^^^
  File "/usr/lib/python3/dist-packages/gpiozero/devices.py", line 602, in value
    return self._read()
           ^^^^^^^^^^^^
  File "/usr/lib/python3/dist-packages/gpiozero/devices.py", line 565, in _read
    self._check_open()
  File "/usr/lib/python3/dist-packages/gpiozero/devices.py", line 587, in _check_open
    raise GPIODeviceClosed(str(e))
gpiozero.exc.GPIODeviceClosed: OutputDevice is closed or uninitialized
2025-04-14 21:23:18,794 [INFO] Starting homing procedure
2025-04-14 21:23:18,798 [INFO] Background threads started
2025-04-14 21:23:25,877 [ERROR] Error in status_broadcast_loop
Traceback (most recent call last):
  File "/usr/lib/python3/dist-packages/gpiozero/devices.py", line 563, in _read
    return self._state_to_value(self.pin.state)
                                ^^^^^^^^^^^^^^
AttributeError: 'NoneType' object has no attribute 'state'

During handling of the above exception, another exception occurred:

Traceback (most recent call last):
  File "/usr/lib/python3/dist-packages/gpiozero/devices.py", line 584, in _check_open
    super()._check_open()
  File "/usr/lib/python3/dist-packages/gpiozero/devices.py", line 213, in _check_open
    raise DeviceClosed(
gpiozero.exc.DeviceClosed: OutputDevice is closed or uninitialized

During handling of the above exception, another exception occurred:

Traceback (most recent call last):
  File "/home/berke/Desktop/PurrfectSpray/Code/app.py", line 241, in status_broadcast_loop
    'laser': laser_pin.value,
             ^^^^^^^^^^^^^^^
  File "/usr/lib/python3/dist-packages/gpiozero/output_devices.py", line 121, in value
    return super().value
           ^^^^^^^^^^^^^
  File "/usr/lib/python3/dist-packages/gpiozero/devices.py", line 602, in value
    return self._read()
           ^^^^^^^^^^^^
  File "/usr/lib/python3/dist-packages/gpiozero/devices.py", line 565, in _read
    self._check_open()
  File "/usr/lib/python3/dist-packages/gpiozero/devices.py", line 587, in _check_open
    raise GPIODeviceClosed(str(e))
gpiozero.exc.GPIODeviceClosed: OutputDevice is closed or uninitialized
2025-04-14 21:23:25,878 [ERROR] Error in fan_loop
Traceback (most recent call last):
  File "/usr/lib/python3/dist-packages/gpiozero/output_devices.py", line 87, in _write
    self.pin.state = self._value_to_state(value)
    ^^^^^^^^^^^^^^
AttributeError: 'NoneType' object has no attribute 'state'

During handling of the above exception, another exception occurred:

Traceback (most recent call last):
  File "/usr/lib/python3/dist-packages/gpiozero/devices.py", line 584, in _check_open
    super()._check_open()
  File "/usr/lib/python3/dist-packages/gpiozero/devices.py", line 213, in _check_open
    raise DeviceClosed(
gpiozero.exc.DeviceClosed: OutputDevice is closed or uninitialized

During handling of the above exception, another exception occurred:

Traceback (most recent call last):
  File "/home/berke/Desktop/PurrfectSpray/Code/app.py", line 228, in fan_loop
    fan_pin.off()
  File "/usr/lib/python3/dist-packages/gpiozero/output_devices.py", line 102, in off
    self._write(False)
  File "/usr/lib/python3/dist-packages/gpiozero/output_devices.py", line 89, in _write
    self._check_open()
  File "/usr/lib/python3/dist-packages/gpiozero/devices.py", line 587, in _check_open
    raise GPIODeviceClosed(str(e))
gpiozero.exc.GPIODeviceClosed: OutputDevice is closed or uninitialized
2025-04-14 21:24:27,255 [INFO] Starting homing procedure
2025-04-14 21:24:27,257 [INFO] Background threads started
2025-04-14 21:24:45,432 [INFO] Homing procedure complete and speed limits set
2025-04-14 21:24:45,432 [INFO] Homing complete
2025-04-14 21:25:21,412 [INFO] Starting homing procedure
2025-04-14 21:25:21,417 [INFO] Background threads started
2025-04-14 21:25:39,169 [INFO] Homing procedure complete and speed limits set
2025-04-14 21:25:39,170 [INFO] Homing complete
2025-04-14 21:25:54,710 [ERROR] Error in status_broadcast_loop
Traceback (most recent call last):
  File "/usr/lib/python3/dist-packages/gpiozero/devices.py", line 563, in _read
    return self._state_to_value(self.pin.state)
                                ^^^^^^^^^^^^^^
AttributeError: 'NoneType' object has no attribute 'state'

During handling of the above exception, another exception occurred:

Traceback (most recent call last):
  File "/usr/lib/python3/dist-packages/gpiozero/devices.py", line 584, in _check_open
    super()._check_open()
  File "/usr/lib/python3/dist-packages/gpiozero/devices.py", line 213, in _check_open
    raise DeviceClosed(
gpiozero.exc.DeviceClosed: OutputDevice is closed or uninitialized

During handling of the above exception, another exception occurred:

Traceback (most recent call last):
  File "/home/berke/Desktop/PurrfectSpray/Code/app.py", line 241, in status_broadcast_loop
    'laser': laser_pin.value,
             ^^^^^^^^^^^^^^^
  File "/usr/lib/python3/dist-packages/gpiozero/output_devices.py", line 121, in value
    return super().value
           ^^^^^^^^^^^^^
  File "/usr/lib/python3/dist-packages/gpiozero/devices.py", line 602, in value
    return self._read()
           ^^^^^^^^^^^^
  File "/usr/lib/python3/dist-packages/gpiozero/devices.py", line 565, in _read
    self._check_open()
  File "/usr/lib/python3/dist-packages/gpiozero/devices.py", line 587, in _check_open
    raise GPIODeviceClosed(str(e))
gpiozero.exc.GPIODeviceClosed: OutputDevice is closed or uninitialized
2025-04-14 21:25:54,753 [ERROR] Error in fan_loop
Traceback (most recent call last):
  File "/usr/lib/python3/dist-packages/gpiozero/output_devices.py", line 87, in _write
    self.pin.state = self._value_to_state(value)
    ^^^^^^^^^^^^^^
AttributeError: 'NoneType' object has no attribute 'state'

During handling of the above exception, another exception occurred:

Traceback (most recent call last):
  File "/usr/lib/python3/dist-packages/gpiozero/devices.py", line 584, in _check_open
    super()._check_open()
  File "/usr/lib/python3/dist-packages/gpiozero/devices.py", line 213, in _check_open
    raise DeviceClosed(
gpiozero.exc.DeviceClosed: OutputDevice is closed or uninitialized

During handling of the above exception, another exception occurred:

Traceback (most recent call last):
  File "/home/berke/Desktop/PurrfectSpray/Code/app.py", line 228, in fan_loop
    fan_pin.off()
  File "/usr/lib/python3/dist-packages/gpiozero/output_devices.py", line 102, in off
    self._write(False)
  File "/usr/lib/python3/dist-packages/gpiozero/output_devices.py", line 89, in _write
    self._check_open()
  File "/usr/lib/python3/dist-packages/gpiozero/devices.py", line 587, in _check_open
    raise GPIODeviceClosed(str(e))
gpiozero.exc.GPIODeviceClosed: OutputDevice is closed or uninitialized
2025-04-14 21:27:01,976 [INFO] Starting homing procedure
2025-04-14 21:27:01,980 [INFO] Background threads started
2025-04-14 21:27:18,055 [INFO] Homing procedure complete and speed limits set
2025-04-14 21:27:18,056 [INFO] Homing complete
2025-04-14 21:27:44,258 [ERROR] Error in fan_loop
Traceback (most recent call last):
  File "/usr/lib/python3/dist-packages/gpiozero/output_devices.py", line 87, in _write
    self.pin.state = self._value_to_state(value)
    ^^^^^^^^^^^^^^
AttributeError: 'NoneType' object has no attribute 'state'

During handling of the above exception, another exception occurred:

Traceback (most recent call last):
  File "/usr/lib/python3/dist-packages/gpiozero/devices.py", line 584, in _check_open
    super()._check_open()
  File "/usr/lib/python3/dist-packages/gpiozero/devices.py", line 213, in _check_open
    raise DeviceClosed(
gpiozero.exc.DeviceClosed: OutputDevice is closed or uninitialized

During handling of the above exception, another exception occurred:

Traceback (most recent call last):
  File "/home/berke/Desktop/PurrfectSpray/Code/app.py", line 228, in fan_loop
    fan_pin.off()
  File "/usr/lib/python3/dist-packages/gpiozero/output_devices.py", line 102, in off
    self._write(False)
  File "/usr/lib/python3/dist-packages/gpiozero/output_devices.py", line 89, in _write
    self._check_open()
  File "/usr/lib/python3/dist-packages/gpiozero/devices.py", line 587, in _check_open
    raise GPIODeviceClosed(str(e))
gpiozero.exc.GPIODeviceClosed: OutputDevice is closed or uninitialized
2025-04-14 21:27:44,264 [ERROR] Error in status_broadcast_loop
Traceback (most recent call last):
  File "/usr/lib/python3/dist-packages/gpiozero/devices.py", line 563, in _read
    return self._state_to_value(self.pin.state)
                                ^^^^^^^^^^^^^^
AttributeError: 'NoneType' object has no attribute 'state'

During handling of the above exception, another exception occurred:

Traceback (most recent call last):
  File "/usr/lib/python3/dist-packages/gpiozero/devices.py", line 584, in _check_open
    super()._check_open()
  File "/usr/lib/python3/dist-packages/gpiozero/devices.py", line 213, in _check_open
    raise DeviceClosed(
gpiozero.exc.DeviceClosed: OutputDevice is closed or uninitialized

During handling of the above exception, another exception occurred:

Traceback (most recent call last):
  File "/home/berke/Desktop/PurrfectSpray/Code/app.py", line 241, in status_broadcast_loop
    'laser': laser_pin.value,
             ^^^^^^^^^^^^^^^
  File "/usr/lib/python3/dist-packages/gpiozero/output_devices.py", line 121, in value
    return super().value
           ^^^^^^^^^^^^^
  File "/usr/lib/python3/dist-packages/gpiozero/devices.py", line 602, in value
    return self._read()
           ^^^^^^^^^^^^
  File "/usr/lib/python3/dist-packages/gpiozero/devices.py", line 565, in _read
    self._check_open()
  File "/usr/lib/python3/dist-packages/gpiozero/devices.py", line 587, in _check_open
    raise GPIODeviceClosed(str(e))
gpiozero.exc.GPIODeviceClosed: OutputDevice is closed or uninitialized
2025-04-14 21:27:49,842 [INFO] Starting homing procedure
2025-04-14 21:27:49,845 [INFO] Background threads started
2025-04-14 21:28:07,055 [INFO] Homing procedure complete and speed limits set
2025-04-14 21:28:07,055 [INFO] Homing complete
2025-04-14 21:28:36,453 [ERROR] Error in status_broadcast_loop
Traceback (most recent call last):
  File "/usr/lib/python3/dist-packages/gpiozero/devices.py", line 563, in _read
    return self._state_to_value(self.pin.state)
                                ^^^^^^^^^^^^^^
AttributeError: 'NoneType' object has no attribute 'state'

During handling of the above exception, another exception occurred:

Traceback (most recent call last):
  File "/usr/lib/python3/dist-packages/gpiozero/devices.py", line 584, in _check_open
    super()._check_open()
  File "/usr/lib/python3/dist-packages/gpiozero/devices.py", line 213, in _check_open
    raise DeviceClosed(
gpiozero.exc.DeviceClosed: OutputDevice is closed or uninitialized

During handling of the above exception, another exception occurred:

Traceback (most recent call last):
  File "/home/berke/Desktop/PurrfectSpray/Code/app.py", line 241, in status_broadcast_loop
    'laser': laser_pin.value,
             ^^^^^^^^^^^^^^^
  File "/usr/lib/python3/dist-packages/gpiozero/output_devices.py", line 121, in value
    return super().value
           ^^^^^^^^^^^^^
  File "/usr/lib/python3/dist-packages/gpiozero/devices.py", line 602, in value
    return self._read()
           ^^^^^^^^^^^^
  File "/usr/lib/python3/dist-packages/gpiozero/devices.py", line 565, in _read
    self._check_open()
  File "/usr/lib/python3/dist-packages/gpiozero/devices.py", line 587, in _check_open
    raise GPIODeviceClosed(str(e))
gpiozero.exc.GPIODeviceClosed: OutputDevice is closed or uninitialized
2025-04-14 21:28:44,111 [INFO] Starting homing procedure
2025-04-14 21:28:44,119 [INFO] Background threads started
2025-04-14 21:29:01,396 [INFO] Homing procedure complete and speed limits set
2025-04-14 21:29:01,396 [INFO] Homing complete
2025-04-14 21:31:34,525 [ERROR] Error in status_broadcast_loop
Traceback (most recent call last):
  File "/usr/lib/python3/dist-packages/gpiozero/devices.py", line 563, in _read
    return self._state_to_value(self.pin.state)
                                ^^^^^^^^^^^^^^
AttributeError: 'NoneType' object has no attribute 'state'

During handling of the above exception, another exception occurred:

Traceback (most recent call last):
  File "/usr/lib/python3/dist-packages/gpiozero/devices.py", line 584, in _check_open
    super()._check_open()
  File "/usr/lib/python3/dist-packages/gpiozero/devices.py", line 213, in _check_open
    raise DeviceClosed(
gpiozero.exc.DeviceClosed: OutputDevice is closed or uninitialized

During handling of the above exception, another exception occurred:

Traceback (most recent call last):
  File "/home/berke/Desktop/PurrfectSpray/Code/app.py", line 241, in status_broadcast_loop
    'laser': laser_pin.value,
             ^^^^^^^^^^^^^^^
  File "/usr/lib/python3/dist-packages/gpiozero/output_devices.py", line 121, in value
    return super().value
           ^^^^^^^^^^^^^
  File "/usr/lib/python3/dist-packages/gpiozero/devices.py", line 602, in value
    return self._read()
           ^^^^^^^^^^^^
  File "/usr/lib/python3/dist-packages/gpiozero/devices.py", line 565, in _read
    self._check_open()
  File "/usr/lib/python3/dist-packages/gpiozero/devices.py", line 587, in _check_open
    raise GPIODeviceClosed(str(e))
gpiozero.exc.GPIODeviceClosed: OutputDevice is closed or uninitialized
2025-04-14 21:31:39,661 [INFO] Starting homing procedure
2025-04-14 21:31:39,664 [INFO] Background threads started
2025-04-14 21:31:59,445 [INFO] Homing procedure complete and speed limits set
2025-04-14 21:31:59,445 [INFO] Homing complete
2025-04-14 21:48:52,845 [ERROR] Error in fan_loop
Traceback (most recent call last):
  File "/usr/lib/python3/dist-packages/gpiozero/output_devices.py", line 87, in _write
    self.pin.state = self._value_to_state(value)
    ^^^^^^^^^^^^^^
AttributeError: 'NoneType' object has no attribute 'state'

During handling of the above exception, another exception occurred:

Traceback (most recent call last):
  File "/usr/lib/python3/dist-packages/gpiozero/devices.py", line 584, in _check_open
    super()._check_open()
  File "/usr/lib/python3/dist-packages/gpiozero/devices.py", line 213, in _check_open
    raise DeviceClosed(
gpiozero.exc.DeviceClosed: OutputDevice is closed or uninitialized

During handling of the above exception, another exception occurred:

Traceback (most recent call last):
  File "/home/berke/Desktop/PurrfectSpray/Code/app.py", line 228, in fan_loop
    fan_pin.off()
  File "/usr/lib/python3/dist-packages/gpiozero/output_devices.py", line 102, in off
    self._write(False)
  File "/usr/lib/python3/dist-packages/gpiozero/output_devices.py", line 89, in _write
    self._check_open()
  File "/usr/lib/python3/dist-packages/gpiozero/devices.py", line 587, in _check_open
    raise GPIODeviceClosed(str(e))
gpiozero.exc.GPIODeviceClosed: OutputDevice is closed or uninitialized
2025-04-14 21:48:52,851 [ERROR] Error in status_broadcast_loop
Traceback (most recent call last):
  File "/usr/lib/python3/dist-packages/gpiozero/devices.py", line 563, in _read
    return self._state_to_value(self.pin.state)
                                ^^^^^^^^^^^^^^
AttributeError: 'NoneType' object has no attribute 'state'

During handling of the above exception, another exception occurred:

Traceback (most recent call last):
  File "/usr/lib/python3/dist-packages/gpiozero/devices.py", line 584, in _check_open
    super()._check_open()
  File "/usr/lib/python3/dist-packages/gpiozero/devices.py", line 213, in _check_open
    raise DeviceClosed(
gpiozero.exc.DeviceClosed: OutputDevice is closed or uninitialized

During handling of the above exception, another exception occurred:

Traceback (most recent call last):
  File "/home/berke/Desktop/PurrfectSpray/Code/app.py", line 241, in status_broadcast_loop
    'laser': laser_pin.value,
             ^^^^^^^^^^^^^^^
  File "/usr/lib/python3/dist-packages/gpiozero/output_devices.py", line 121, in value
    return super().value
           ^^^^^^^^^^^^^
  File "/usr/lib/python3/dist-packages/gpiozero/devices.py", line 602, in value
    return self._read()
           ^^^^^^^^^^^^
  File "/usr/lib/python3/dist-packages/gpiozero/devices.py", line 565, in _read
    self._check_open()
  File "/usr/lib/python3/dist-packages/gpiozero/devices.py", line 587, in _check_open
    raise GPIODeviceClosed(str(e))
gpiozero.exc.GPIODeviceClosed: OutputDevice is closed or uninitialized
2025-04-14 21:48:58,473 [INFO] Starting homing procedure
2025-04-14 21:48:58,477 [INFO] Background threads started
2025-04-14 21:49:15,068 [INFO] Homing procedure complete and speed limits set
2025-04-14 21:49:15,068 [INFO] Homing complete
2025-04-14 22:03:09,427 [INFO] Starting homing procedure
2025-04-14 22:03:09,431 [INFO] Background threads started
2025-04-14 22:03:35,088 [ERROR] Error during homing_procedure
Traceback (most recent call last):
  File "/usr/lib/python3/dist-packages/gpiozero/devices.py", line 563, in _read
    return self._state_to_value(self.pin.state)
                                ^^^^^^^^^^^^^^
AttributeError: 'NoneType' object has no attribute 'state'

During handling of the above exception, another exception occurred:

Traceback (most recent call last):
  File "/usr/lib/python3/dist-packages/gpiozero/devices.py", line 584, in _check_open
    super()._check_open()
  File "/usr/lib/python3/dist-packages/gpiozero/devices.py", line 213, in _check_open
    raise DeviceClosed(
gpiozero.exc.DeviceClosed: DigitalInputDevice is closed or uninitialized

During handling of the above exception, another exception occurred:

Traceback (most recent call last):
  File "/home/berke/Desktop/PurrfectSpray/Code/motors.py", line 76, in homing_procedure
    home_motor(Motor1, hall_sensor_1, 1)
  File "/home/berke/Desktop/PurrfectSpray/Code/motors.py", line 47, in home_motor
    while not read_sensor():
              ^^^^^^^^^^^^^
  File "/home/berke/Desktop/PurrfectSpray/Code/motors.py", line 36, in read_sensor
    return not hall_sensor.value
               ^^^^^^^^^^^^^^^^^
  File "/usr/lib/python3/dist-packages/gpiozero/devices.py", line 602, in value
    return self._read()
           ^^^^^^^^^^^^
  File "/usr/lib/python3/dist-packages/gpiozero/devices.py", line 565, in _read
    self._check_open()
  File "/usr/lib/python3/dist-packages/gpiozero/devices.py", line 587, in _check_open
    raise GPIODeviceClosed(str(e))
gpiozero.exc.GPIODeviceClosed: DigitalInputDevice is closed or uninitialized
2025-04-14 22:03:35,193 [INFO] Homing complete
2025-04-14 22:03:35,203 [ERROR] Error in motor_loop
Traceback (most recent call last):
  File "/usr/lib/python3/dist-packages/gpiozero/output_devices.py", line 87, in _write
    self.pin.state = self._value_to_state(value)
    ^^^^^^^^^^^^^^
AttributeError: 'NoneType' object has no attribute 'state'

During handling of the above exception, another exception occurred:

Traceback (most recent call last):
  File "/usr/lib/python3/dist-packages/gpiozero/devices.py", line 584, in _check_open
    super()._check_open()
  File "/usr/lib/python3/dist-packages/gpiozero/devices.py", line 213, in _check_open
    raise DeviceClosed(
gpiozero.exc.DeviceClosed: DigitalOutputDevice is closed or uninitialized

During handling of the above exception, another exception occurred:

Traceback (most recent call last):
  File "/home/berke/Desktop/PurrfectSpray/Code/app.py", line 209, in motor_loop
    Motor1.run()
  File "/home/berke/Desktop/PurrfectSpray/Code/AccelStepper.py", line 134, in run
    if self.run_speed():
       ^^^^^^^^^^^^^^^^
  File "/home/berke/Desktop/PurrfectSpray/Code/AccelStepper.py", line 75, in run_speed
    self.step(self._currentPos)
  File "/home/berke/Desktop/PurrfectSpray/Code/AccelStepper.py", line 180, in step
    self.step1(step)
  File "/home/berke/Desktop/PurrfectSpray/Code/AccelStepper.py", line 212, in step1
    self.set_output_pins(0b10 if self._direction else 0b00)
  File "/home/berke/Desktop/PurrfectSpray/Code/AccelStepper.py", line 203, in set_output_pins
    self._pins[i].off() if not self._pinInverted[i] else self._pins[i].on()
    ^^^^^^^^^^^^^^^^^^^
  File "/usr/lib/python3/dist-packages/gpiozero/output_devices.py", line 214, in off
    self._write(False)
  File "/usr/lib/python3/dist-packages/gpiozero/output_devices.py", line 89, in _write
    self._check_open()
  File "/usr/lib/python3/dist-packages/gpiozero/devices.py", line 587, in _check_open
    raise GPIODeviceClosed(str(e))
gpiozero.exc.GPIODeviceClosed: DigitalOutputDevice is closed or uninitialized
2025-04-14 22:07:25,190 [INFO] Starting homing procedure
2025-04-14 22:07:25,195 [INFO] Background threads started
2025-04-14 22:07:35,329 [INFO] Homing procedure complete and speed limits set
2025-04-14 22:07:35,332 [INFO] Homing complete
2025-04-14 22:09:27,907 [ERROR] Error in fan_loop
Traceback (most recent call last):
  File "/usr/lib/python3/dist-packages/gpiozero/output_devices.py", line 87, in _write
    self.pin.state = self._value_to_state(value)
    ^^^^^^^^^^^^^^
AttributeError: 'NoneType' object has no attribute 'state'

During handling of the above exception, another exception occurred:

Traceback (most recent call last):
  File "/usr/lib/python3/dist-packages/gpiozero/devices.py", line 584, in _check_open
    super()._check_open()
  File "/usr/lib/python3/dist-packages/gpiozero/devices.py", line 213, in _check_open
    raise DeviceClosed(
gpiozero.exc.DeviceClosed: OutputDevice is closed or uninitialized

During handling of the above exception, another exception occurred:

Traceback (most recent call last):
  File "/home/berke/Desktop/PurrfectSpray/Code/app.py", line 228, in fan_loop
    fan_pin.off()
  File "/usr/lib/python3/dist-packages/gpiozero/output_devices.py", line 102, in off
    self._write(False)
  File "/usr/lib/python3/dist-packages/gpiozero/output_devices.py", line 89, in _write
    self._check_open()
  File "/usr/lib/python3/dist-packages/gpiozero/devices.py", line 587, in _check_open
    raise GPIODeviceClosed(str(e))
gpiozero.exc.GPIODeviceClosed: OutputDevice is closed or uninitialized
2025-04-14 22:09:33,260 [INFO] Starting homing procedure
2025-04-14 22:09:33,264 [INFO] Background threads started
2025-04-14 22:09:48,551 [ERROR] Error during homing_procedure
Traceback (most recent call last):
  File "/usr/lib/python3/dist-packages/gpiozero/devices.py", line 563, in _read
    return self._state_to_value(self.pin.state)
                                ^^^^^^^^^^^^^^
AttributeError: 'NoneType' object has no attribute 'state'

During handling of the above exception, another exception occurred:

Traceback (most recent call last):
  File "/usr/lib/python3/dist-packages/gpiozero/devices.py", line 584, in _check_open
    super()._check_open()
  File "/usr/lib/python3/dist-packages/gpiozero/devices.py", line 213, in _check_open
    raise DeviceClosed(
gpiozero.exc.DeviceClosed: DigitalInputDevice is closed or uninitialized

During handling of the above exception, another exception occurred:

Traceback (most recent call last):
  File "/home/berke/Desktop/PurrfectSpray/Code/motors.py", line 76, in homing_procedure
    home_motor(Motor1, hall_sensor_1, 1)
  File "/home/berke/Desktop/PurrfectSpray/Code/motors.py", line 47, in home_motor
    while not read_sensor():
              ^^^^^^^^^^^^^
  File "/home/berke/Desktop/PurrfectSpray/Code/motors.py", line 36, in read_sensor
    return not hall_sensor.value
               ^^^^^^^^^^^^^^^^^
  File "/usr/lib/python3/dist-packages/gpiozero/devices.py", line 602, in value
    return self._read()
           ^^^^^^^^^^^^
  File "/usr/lib/python3/dist-packages/gpiozero/devices.py", line 565, in _read
    self._check_open()
  File "/usr/lib/python3/dist-packages/gpiozero/devices.py", line 587, in _check_open
    raise GPIODeviceClosed(str(e))
gpiozero.exc.GPIODeviceClosed: DigitalInputDevice is closed or uninitialized
2025-04-14 22:09:48,553 [INFO] Homing complete
2025-04-14 22:09:48,554 [ERROR] Error in motor_loop
Traceback (most recent call last):
  File "/usr/lib/python3/dist-packages/gpiozero/output_devices.py", line 87, in _write
    self.pin.state = self._value_to_state(value)
    ^^^^^^^^^^^^^^
AttributeError: 'NoneType' object has no attribute 'state'

During handling of the above exception, another exception occurred:

Traceback (most recent call last):
  File "/usr/lib/python3/dist-packages/gpiozero/devices.py", line 584, in _check_open
    super()._check_open()
  File "/usr/lib/python3/dist-packages/gpiozero/devices.py", line 213, in _check_open
    raise DeviceClosed(
gpiozero.exc.DeviceClosed: DigitalOutputDevice is closed or uninitialized

During handling of the above exception, another exception occurred:

Traceback (most recent call last):
  File "/home/berke/Desktop/PurrfectSpray/Code/app.py", line 209, in motor_loop
    Motor1.run()
  File "/home/berke/Desktop/PurrfectSpray/Code/AccelStepper.py", line 134, in run
    if self.run_speed():
       ^^^^^^^^^^^^^^^^
  File "/home/berke/Desktop/PurrfectSpray/Code/AccelStepper.py", line 75, in run_speed
    self.step(self._currentPos)
  File "/home/berke/Desktop/PurrfectSpray/Code/AccelStepper.py", line 180, in step
    self.step1(step)
  File "/home/berke/Desktop/PurrfectSpray/Code/AccelStepper.py", line 212, in step1
    self.set_output_pins(0b10 if self._direction else 0b00)
  File "/home/berke/Desktop/PurrfectSpray/Code/AccelStepper.py", line 203, in set_output_pins
    self._pins[i].off() if not self._pinInverted[i] else self._pins[i].on()
    ^^^^^^^^^^^^^^^^^^^
  File "/usr/lib/python3/dist-packages/gpiozero/output_devices.py", line 214, in off
    self._write(False)
  File "/usr/lib/python3/dist-packages/gpiozero/output_devices.py", line 89, in _write
    self._check_open()
  File "/usr/lib/python3/dist-packages/gpiozero/devices.py", line 587, in _check_open
    raise GPIODeviceClosed(str(e))
gpiozero.exc.GPIODeviceClosed: DigitalOutputDevice is closed or uninitialized
2025-04-14 22:09:48,704 [ERROR] Error in status_broadcast_loop
Traceback (most recent call last):
  File "/usr/lib/python3/dist-packages/gpiozero/devices.py", line 563, in _read
    return self._state_to_value(self.pin.state)
                                ^^^^^^^^^^^^^^
AttributeError: 'NoneType' object has no attribute 'state'

During handling of the above exception, another exception occurred:

Traceback (most recent call last):
  File "/usr/lib/python3/dist-packages/gpiozero/devices.py", line 584, in _check_open
    super()._check_open()
  File "/usr/lib/python3/dist-packages/gpiozero/devices.py", line 213, in _check_open
    raise DeviceClosed(
gpiozero.exc.DeviceClosed: OutputDevice is closed or uninitialized

During handling of the above exception, another exception occurred:

Traceback (most recent call last):
  File "/home/berke/Desktop/PurrfectSpray/Code/app.py", line 241, in status_broadcast_loop
    'laser': laser_pin.value,
             ^^^^^^^^^^^^^^^
  File "/usr/lib/python3/dist-packages/gpiozero/output_devices.py", line 121, in value
    return super().value
           ^^^^^^^^^^^^^
  File "/usr/lib/python3/dist-packages/gpiozero/devices.py", line 602, in value
    return self._read()
           ^^^^^^^^^^^^
  File "/usr/lib/python3/dist-packages/gpiozero/devices.py", line 565, in _read
    self._check_open()
  File "/usr/lib/python3/dist-packages/gpiozero/devices.py", line 587, in _check_open
    raise GPIODeviceClosed(str(e))
gpiozero.exc.GPIODeviceClosed: OutputDevice is closed or uninitialized
2025-04-14 22:10:10,973 [INFO] Starting homing procedure
2025-04-14 22:10:10,977 [INFO] Background threads started
2025-04-14 22:10:24,303 [INFO] Homing procedure complete and speed limits set
2025-04-14 22:10:24,304 [INFO] Homing complete
2025-04-14 22:13:52,903 [INFO] Starting homing procedure
2025-04-14 22:13:52,905 [INFO] Background threads started
2025-04-14 22:14:09,339 [INFO] Homing procedure complete and speed limits set
2025-04-14 22:14:09,339 [INFO] Homing complete
2025-04-14 22:15:17,657 [INFO] Starting homing procedure
2025-04-14 22:15:17,660 [INFO] Background threads started
2025-04-14 22:15:33,096 [INFO] Homing procedure complete and speed limits set
2025-04-14 22:15:33,096 [INFO] Homing complete
2025-04-14 22:18:04,945 [ERROR] Error in status_broadcast_loop
Traceback (most recent call last):
  File "/usr/lib/python3/dist-packages/gpiozero/devices.py", line 563, in _read
    return self._state_to_value(self.pin.state)
                                ^^^^^^^^^^^^^^
AttributeError: 'NoneType' object has no attribute 'state'

During handling of the above exception, another exception occurred:

Traceback (most recent call last):
  File "/usr/lib/python3/dist-packages/gpiozero/devices.py", line 584, in _check_open
    super()._check_open()
  File "/usr/lib/python3/dist-packages/gpiozero/devices.py", line 213, in _check_open
    raise DeviceClosed(
gpiozero.exc.DeviceClosed: OutputDevice is closed or uninitialized

During handling of the above exception, another exception occurred:

Traceback (most recent call last):
  File "/home/berke/Desktop/PurrfectSpray/Code/app.py", line 241, in status_broadcast_loop
    'laser': laser_pin.value,
             ^^^^^^^^^^^^^^^
  File "/usr/lib/python3/dist-packages/gpiozero/output_devices.py", line 121, in value
    return super().value
           ^^^^^^^^^^^^^
  File "/usr/lib/python3/dist-packages/gpiozero/devices.py", line 602, in value
    return self._read()
           ^^^^^^^^^^^^
  File "/usr/lib/python3/dist-packages/gpiozero/devices.py", line 565, in _read
    self._check_open()
  File "/usr/lib/python3/dist-packages/gpiozero/devices.py", line 587, in _check_open
    raise GPIODeviceClosed(str(e))
gpiozero.exc.GPIODeviceClosed: OutputDevice is closed or uninitialized
2025-04-14 22:18:10,639 [INFO] Starting homing procedure
2025-04-14 22:18:10,641 [INFO] Background threads started
2025-04-14 22:18:24,935 [INFO] Homing procedure complete and speed limits set
2025-04-14 22:18:24,936 [INFO] Homing complete
2025-04-14 22:19:09,849 [INFO] Starting homing procedure
2025-04-14 22:19:09,853 [INFO] Background threads started
2025-04-14 22:19:24,170 [INFO] Homing procedure complete and speed limits set
2025-04-14 22:19:24,171 [INFO] Homing complete
2025-04-14 22:20:04,400 [ERROR] Error in status_broadcast_loop
Traceback (most recent call last):
  File "/usr/lib/python3/dist-packages/gpiozero/devices.py", line 563, in _read
    return self._state_to_value(self.pin.state)
                                ^^^^^^^^^^^^^^
AttributeError: 'NoneType' object has no attribute 'state'

During handling of the above exception, another exception occurred:

Traceback (most recent call last):
  File "/usr/lib/python3/dist-packages/gpiozero/devices.py", line 584, in _check_open
    super()._check_open()
  File "/usr/lib/python3/dist-packages/gpiozero/devices.py", line 213, in _check_open
    raise DeviceClosed(
gpiozero.exc.DeviceClosed: OutputDevice is closed or uninitialized

During handling of the above exception, another exception occurred:

Traceback (most recent call last):
  File "/home/berke/Desktop/PurrfectSpray/Code/app.py", line 241, in status_broadcast_loop
    'laser': laser_pin.value,
             ^^^^^^^^^^^^^^^
  File "/usr/lib/python3/dist-packages/gpiozero/output_devices.py", line 121, in value
    return super().value
           ^^^^^^^^^^^^^
  File "/usr/lib/python3/dist-packages/gpiozero/devices.py", line 602, in value
    return self._read()
           ^^^^^^^^^^^^
  File "/usr/lib/python3/dist-packages/gpiozero/devices.py", line 565, in _read
    self._check_open()
  File "/usr/lib/python3/dist-packages/gpiozero/devices.py", line 587, in _check_open
    raise GPIODeviceClosed(str(e))
gpiozero.exc.GPIODeviceClosed: OutputDevice is closed or uninitialized
2025-04-14 22:31:59,633 [INFO] Starting homing procedure
2025-04-14 22:31:59,638 [INFO] Background threads started
2025-04-14 22:32:16,411 [INFO] Homing procedure complete and speed limits set
2025-04-14 22:32:16,411 [INFO] Homing complete
2025-04-14 22:33:14,434 [ERROR] Error in status_broadcast_loop
Traceback (most recent call last):
  File "/usr/lib/python3/dist-packages/gpiozero/devices.py", line 563, in _read
    return self._state_to_value(self.pin.state)
                                ^^^^^^^^^^^^^^
AttributeError: 'NoneType' object has no attribute 'state'

During handling of the above exception, another exception occurred:

Traceback (most recent call last):
  File "/usr/lib/python3/dist-packages/gpiozero/devices.py", line 584, in _check_open
    super()._check_open()
  File "/usr/lib/python3/dist-packages/gpiozero/devices.py", line 213, in _check_open
    raise DeviceClosed(
gpiozero.exc.DeviceClosed: OutputDevice is closed or uninitialized

During handling of the above exception, another exception occurred:

Traceback (most recent call last):
  File "/home/berke/Desktop/PurrfectSpray/Code/app.py", line 241, in status_broadcast_loop
    'laser': laser_pin.value,
             ^^^^^^^^^^^^^^^
  File "/usr/lib/python3/dist-packages/gpiozero/output_devices.py", line 121, in value
    return super().value
           ^^^^^^^^^^^^^
  File "/usr/lib/python3/dist-packages/gpiozero/devices.py", line 602, in value
    return self._read()
           ^^^^^^^^^^^^
  File "/usr/lib/python3/dist-packages/gpiozero/devices.py", line 565, in _read
    self._check_open()
  File "/usr/lib/python3/dist-packages/gpiozero/devices.py", line 587, in _check_open
    raise GPIODeviceClosed(str(e))
gpiozero.exc.GPIODeviceClosed: OutputDevice is closed or uninitialized
2025-04-14 22:33:28,921 [INFO] Starting homing procedure
2025-04-14 22:33:28,927 [INFO] Background threads started
2025-04-14 22:33:43,366 [INFO] Homing procedure complete and speed limits set
2025-04-14 22:33:43,367 [INFO] Homing complete
2025-04-14 22:35:15,394 [ERROR] Error in status_broadcast_loop
Traceback (most recent call last):
  File "/usr/lib/python3/dist-packages/gpiozero/devices.py", line 563, in _read
    return self._state_to_value(self.pin.state)
                                ^^^^^^^^^^^^^^
AttributeError: 'NoneType' object has no attribute 'state'

During handling of the above exception, another exception occurred:

Traceback (most recent call last):
  File "/usr/lib/python3/dist-packages/gpiozero/devices.py", line 584, in _check_open
    super()._check_open()
  File "/usr/lib/python3/dist-packages/gpiozero/devices.py", line 213, in _check_open
    raise DeviceClosed(
gpiozero.exc.DeviceClosed: OutputDevice is closed or uninitialized

During handling of the above exception, another exception occurred:

Traceback (most recent call last):
  File "/home/berke/Desktop/PurrfectSpray/Code/app.py", line 241, in status_broadcast_loop
    'laser': laser_pin.value,
             ^^^^^^^^^^^^^^^
  File "/usr/lib/python3/dist-packages/gpiozero/output_devices.py", line 121, in value
    return super().value
           ^^^^^^^^^^^^^
  File "/usr/lib/python3/dist-packages/gpiozero/devices.py", line 602, in value
    return self._read()
           ^^^^^^^^^^^^
  File "/usr/lib/python3/dist-packages/gpiozero/devices.py", line 565, in _read
    self._check_open()
  File "/usr/lib/python3/dist-packages/gpiozero/devices.py", line 587, in _check_open
    raise GPIODeviceClosed(str(e))
gpiozero.exc.GPIODeviceClosed: OutputDevice is closed or uninitialized
2025-04-14 22:35:20,921 [INFO] Starting homing procedure
2025-04-14 22:35:20,924 [INFO] Background threads started
2025-04-14 22:35:38,340 [INFO] Homing procedure complete and speed limits set
2025-04-14 22:35:38,341 [INFO] Homing complete
2025-04-14 22:36:53,940 [INFO] Starting homing procedure
2025-04-14 22:36:53,942 [INFO] Background threads started
2025-04-14 22:37:10,536 [INFO] Homing procedure complete and speed limits set
2025-04-14 22:37:10,536 [INFO] Homing complete
2025-04-14 22:38:04,425 [ERROR] Error in fan_loop
Traceback (most recent call last):
  File "/usr/lib/python3/dist-packages/gpiozero/output_devices.py", line 87, in _write
    self.pin.state = self._value_to_state(value)
    ^^^^^^^^^^^^^^
AttributeError: 'NoneType' object has no attribute 'state'

During handling of the above exception, another exception occurred:

Traceback (most recent call last):
  File "/usr/lib/python3/dist-packages/gpiozero/devices.py", line 584, in _check_open
    super()._check_open()
  File "/usr/lib/python3/dist-packages/gpiozero/devices.py", line 213, in _check_open
    raise DeviceClosed(
gpiozero.exc.DeviceClosed: OutputDevice is closed or uninitialized

During handling of the above exception, another exception occurred:

Traceback (most recent call last):
  File "/home/berke/Desktop/PurrfectSpray/Code/app.py", line 228, in fan_loop
    fan_pin.off()
  File "/usr/lib/python3/dist-packages/gpiozero/output_devices.py", line 102, in off
    self._write(False)
  File "/usr/lib/python3/dist-packages/gpiozero/output_devices.py", line 89, in _write
    self._check_open()
  File "/usr/lib/python3/dist-packages/gpiozero/devices.py", line 587, in _check_open
    raise GPIODeviceClosed(str(e))
gpiozero.exc.GPIODeviceClosed: OutputDevice is closed or uninitialized
2025-04-14 23:42:57,099 [INFO] Starting homing procedure
2025-04-14 23:42:57,104 [INFO] Background threads started
2025-04-14 23:43:09,641 [ERROR] Error during homing_procedure
Traceback (most recent call last):
  File "/usr/lib/python3/dist-packages/gpiozero/devices.py", line 563, in _read
    return self._state_to_value(self.pin.state)
                                ^^^^^^^^^^^^^^
AttributeError: 'NoneType' object has no attribute 'state'

During handling of the above exception, another exception occurred:

Traceback (most recent call last):
  File "/usr/lib/python3/dist-packages/gpiozero/devices.py", line 584, in _check_open
    super()._check_open()
  File "/usr/lib/python3/dist-packages/gpiozero/devices.py", line 213, in _check_open
    raise DeviceClosed(
gpiozero.exc.DeviceClosed: DigitalInputDevice is closed or uninitialized

During handling of the above exception, another exception occurred:

Traceback (most recent call last):
  File "/home/berke/Desktop/PurrfectSpray/Code/motors.py", line 77, in homing_procedure
    home_motor(Motor2, hall_sensor_2, 2)
  File "/home/berke/Desktop/PurrfectSpray/Code/motors.py", line 54, in home_motor
    while read_sensor():
          ^^^^^^^^^^^^^
  File "/home/berke/Desktop/PurrfectSpray/Code/motors.py", line 36, in read_sensor
    return not hall_sensor.value
               ^^^^^^^^^^^^^^^^^
  File "/usr/lib/python3/dist-packages/gpiozero/devices.py", line 602, in value
    return self._read()
           ^^^^^^^^^^^^
  File "/usr/lib/python3/dist-packages/gpiozero/devices.py", line 565, in _read
    self._check_open()
  File "/usr/lib/python3/dist-packages/gpiozero/devices.py", line 587, in _check_open
    raise GPIODeviceClosed(str(e))
gpiozero.exc.GPIODeviceClosed: DigitalInputDevice is closed or uninitialized
2025-04-14 23:43:09,646 [INFO] Homing complete
2025-04-14 23:43:09,646 [ERROR] Error in motor_loop
Traceback (most recent call last):
  File "/usr/lib/python3/dist-packages/gpiozero/output_devices.py", line 87, in _write
    self.pin.state = self._value_to_state(value)
    ^^^^^^^^^^^^^^
AttributeError: 'NoneType' object has no attribute 'state'

During handling of the above exception, another exception occurred:

Traceback (most recent call last):
  File "/usr/lib/python3/dist-packages/gpiozero/devices.py", line 584, in _check_open
    super()._check_open()
  File "/usr/lib/python3/dist-packages/gpiozero/devices.py", line 213, in _check_open
    raise DeviceClosed(
gpiozero.exc.DeviceClosed: DigitalOutputDevice is closed or uninitialized

During handling of the above exception, another exception occurred:

Traceback (most recent call last):
  File "/home/berke/Desktop/PurrfectSpray/Code/app.py", line 210, in motor_loop
    Motor2.run()
  File "/home/berke/Desktop/PurrfectSpray/Code/AccelStepper.py", line 134, in run
    if self.run_speed():
       ^^^^^^^^^^^^^^^^
  File "/home/berke/Desktop/PurrfectSpray/Code/AccelStepper.py", line 75, in run_speed
    self.step(self._currentPos)
  File "/home/berke/Desktop/PurrfectSpray/Code/AccelStepper.py", line 180, in step
    self.step1(step)
  File "/home/berke/Desktop/PurrfectSpray/Code/AccelStepper.py", line 212, in step1
    self.set_output_pins(0b10 if self._direction else 0b00)
  File "/home/berke/Desktop/PurrfectSpray/Code/AccelStepper.py", line 203, in set_output_pins
    self._pins[i].off() if not self._pinInverted[i] else self._pins[i].on()
    ^^^^^^^^^^^^^^^^^^^
  File "/usr/lib/python3/dist-packages/gpiozero/output_devices.py", line 214, in off
    self._write(False)
  File "/usr/lib/python3/dist-packages/gpiozero/output_devices.py", line 89, in _write
    self._check_open()
  File "/usr/lib/python3/dist-packages/gpiozero/devices.py", line 587, in _check_open
    raise GPIODeviceClosed(str(e))
gpiozero.exc.GPIODeviceClosed: DigitalOutputDevice is closed or uninitialized
2025-04-16 00:47:46,350 [INFO] Starting homing procedure
2025-04-16 00:47:46,358 [INFO] Background threads started
2025-04-16 00:48:03,002 [INFO] Homing procedure complete and speed limits set
2025-04-16 00:48:03,003 [INFO] Homing complete
2025-04-16 00:52:10,271 [INFO] Starting homing procedure
2025-04-16 00:52:10,280 [INFO] Background threads started
2025-04-16 00:52:27,239 [INFO] Homing procedure complete and speed limits set
2025-04-16 00:52:27,240 [INFO] Homing complete
2025-04-16 00:53:43,106 [ERROR] Error in fan_loop
Traceback (most recent call last):
  File "/usr/lib/python3/dist-packages/gpiozero/output_devices.py", line 87, in _write
    self.pin.state = self._value_to_state(value)
    ^^^^^^^^^^^^^^
AttributeError: 'NoneType' object has no attribute 'state'

During handling of the above exception, another exception occurred:

Traceback (most recent call last):
  File "/usr/lib/python3/dist-packages/gpiozero/devices.py", line 584, in _check_open
    super()._check_open()
  File "/usr/lib/python3/dist-packages/gpiozero/devices.py", line 213, in _check_open
    raise DeviceClosed(
gpiozero.exc.DeviceClosed: OutputDevice is closed or uninitialized

During handling of the above exception, another exception occurred:

Traceback (most recent call last):
  File "/home/berke/Desktop/PurrfectSpray/Code/app.py", line 265, in fan_loop
    fan_pin.off()
  File "/usr/lib/python3/dist-packages/gpiozero/output_devices.py", line 102, in off
    self._write(False)
  File "/usr/lib/python3/dist-packages/gpiozero/output_devices.py", line 89, in _write
    self._check_open()
  File "/usr/lib/python3/dist-packages/gpiozero/devices.py", line 587, in _check_open
    raise GPIODeviceClosed(str(e))
gpiozero.exc.GPIODeviceClosed: OutputDevice is closed or uninitialized
2025-04-16 00:53:48,498 [INFO] Starting homing procedure
2025-04-16 00:53:48,501 [INFO] Background threads started
2025-04-16 00:54:05,362 [INFO] Homing procedure complete and speed limits set
2025-04-16 00:54:05,363 [INFO] Homing complete
2025-04-16 00:54:47,476 [INFO] Starting homing procedure
2025-04-16 00:54:47,483 [INFO] Background threads started
2025-04-16 00:55:03,873 [INFO] Homing procedure complete and speed limits set
2025-04-16 00:55:03,874 [INFO] Homing complete
2025-04-16 01:01:17,002 [INFO] Starting homing procedure
2025-04-16 01:01:17,008 [INFO] Background threads started
2025-04-16 01:01:34,298 [INFO] Homing procedure complete and speed limits set
2025-04-16 01:01:34,299 [INFO] Homing complete
2025-04-16 16:57:49,700 [INFO] Starting homing procedure
2025-04-16 16:57:49,709 [ERROR] Error in status_broadcast_loop
Traceback (most recent call last):
  File "/home/berke/Desktop/PurrfectSpray/Code/app.py", line 293, in status_broadcast_loop
    'homing': homing_complete,
              ^^^^^^^^^^^^^^^
NameError: name 'homing_complete' is not defined
2025-04-16 16:57:49,819 [ERROR] Error during homing_procedure
Traceback (most recent call last):
  File "/usr/lib/python3/dist-packages/gpiozero/devices.py", line 563, in _read
    return self._state_to_value(self.pin.state)
                                ^^^^^^^^^^^^^^
AttributeError: 'NoneType' object has no attribute 'state'

During handling of the above exception, another exception occurred:

Traceback (most recent call last):
  File "/usr/lib/python3/dist-packages/gpiozero/devices.py", line 584, in _check_open
    super()._check_open()
  File "/usr/lib/python3/dist-packages/gpiozero/devices.py", line 213, in _check_open
    raise DeviceClosed(
gpiozero.exc.DeviceClosed: DigitalInputDevice is closed or uninitialized

During handling of the above exception, another exception occurred:

Traceback (most recent call last):
  File "/home/berke/Desktop/PurrfectSpray/Code/motors.py", line 76, in homing_procedure
    home_motor(Motor1, hall_sensor_1, 1)
  File "/home/berke/Desktop/PurrfectSpray/Code/motors.py", line 41, in home_motor
    while read_sensor():
          ^^^^^^^^^^^^^
  File "/home/berke/Desktop/PurrfectSpray/Code/motors.py", line 36, in read_sensor
    return not hall_sensor.value
               ^^^^^^^^^^^^^^^^^
  File "/usr/lib/python3/dist-packages/gpiozero/devices.py", line 602, in value
    return self._read()
           ^^^^^^^^^^^^
  File "/usr/lib/python3/dist-packages/gpiozero/devices.py", line 565, in _read
    self._check_open()
  File "/usr/lib/python3/dist-packages/gpiozero/devices.py", line 587, in _check_open
    raise GPIODeviceClosed(str(e))
gpiozero.exc.GPIODeviceClosed: DigitalInputDevice is closed or uninitialized
2025-04-16 16:57:49,825 [INFO] Homing complete
2025-04-16 16:57:49,831 [ERROR] Error in motor_loop
Traceback (most recent call last):
  File "/home/berke/Desktop/PurrfectSpray/Code/app.py", line 234, in motor_loop
    if motor_active and homing_complete and app_globals.target_lock.is_set():
       ^^^^^^^^^^^^
NameError: name 'motor_active' is not defined
2025-04-16 17:02:28,130 [INFO] Starting homing procedure
2025-04-16 17:02:28,252 [ERROR] Error during homing_procedure
Traceback (most recent call last):
  File "/usr/lib/python3/dist-packages/gpiozero/devices.py", line 563, in _read
    return self._state_to_value(self.pin.state)
                                ^^^^^^^^^^^^^^
AttributeError: 'NoneType' object has no attribute 'state'

During handling of the above exception, another exception occurred:

Traceback (most recent call last):
  File "/usr/lib/python3/dist-packages/gpiozero/devices.py", line 584, in _check_open
    super()._check_open()
  File "/usr/lib/python3/dist-packages/gpiozero/devices.py", line 213, in _check_open
    raise DeviceClosed(
gpiozero.exc.DeviceClosed: DigitalInputDevice is closed or uninitialized

During handling of the above exception, another exception occurred:

Traceback (most recent call last):
  File "/home/berke/Desktop/PurrfectSpray/Code/motors.py", line 76, in homing_procedure
    home_motor(Motor1, hall_sensor_1, 1)
  File "/home/berke/Desktop/PurrfectSpray/Code/motors.py", line 41, in home_motor
    while read_sensor():
          ^^^^^^^^^^^^^
  File "/home/berke/Desktop/PurrfectSpray/Code/motors.py", line 36, in read_sensor
    return not hall_sensor.value
               ^^^^^^^^^^^^^^^^^
  File "/usr/lib/python3/dist-packages/gpiozero/devices.py", line 602, in value
    return self._read()
           ^^^^^^^^^^^^
  File "/usr/lib/python3/dist-packages/gpiozero/devices.py", line 565, in _read
    self._check_open()
  File "/usr/lib/python3/dist-packages/gpiozero/devices.py", line 587, in _check_open
    raise GPIODeviceClosed(str(e))
gpiozero.exc.GPIODeviceClosed: DigitalInputDevice is closed or uninitialized
2025-04-16 17:02:28,257 [INFO] Homing complete
2025-04-16 17:02:28,258 [ERROR] Error in motor_loop
Traceback (most recent call last):
  File "/usr/lib/python3/dist-packages/gpiozero/output_devices.py", line 87, in _write
    self.pin.state = self._value_to_state(value)
    ^^^^^^^^^^^^^^
AttributeError: 'NoneType' object has no attribute 'state'

During handling of the above exception, another exception occurred:

Traceback (most recent call last):
  File "/usr/lib/python3/dist-packages/gpiozero/devices.py", line 584, in _check_open
    super()._check_open()
  File "/usr/lib/python3/dist-packages/gpiozero/devices.py", line 213, in _check_open
    raise DeviceClosed(
gpiozero.exc.DeviceClosed: DigitalOutputDevice is closed or uninitialized

During handling of the above exception, another exception occurred:

Traceback (most recent call last):
  File "/home/berke/Desktop/PurrfectSpray/Code/app.py", line 263, in motor_loop
    Motor1.run()
  File "/home/berke/Desktop/PurrfectSpray/Code/AccelStepper.py", line 134, in run
    if self.run_speed():
       ^^^^^^^^^^^^^^^^
  File "/home/berke/Desktop/PurrfectSpray/Code/AccelStepper.py", line 75, in run_speed
    self.step(self._currentPos)
  File "/home/berke/Desktop/PurrfectSpray/Code/AccelStepper.py", line 180, in step
    self.step1(step)
  File "/home/berke/Desktop/PurrfectSpray/Code/AccelStepper.py", line 212, in step1
    self.set_output_pins(0b10 if self._direction else 0b00)
  File "/home/berke/Desktop/PurrfectSpray/Code/AccelStepper.py", line 203, in set_output_pins
    self._pins[i].off() if not self._pinInverted[i] else self._pins[i].on()
    ^^^^^^^^^^^^^^^^^^^
  File "/usr/lib/python3/dist-packages/gpiozero/output_devices.py", line 214, in off
    self._write(False)
  File "/usr/lib/python3/dist-packages/gpiozero/output_devices.py", line 89, in _write
    self._check_open()
  File "/usr/lib/python3/dist-packages/gpiozero/devices.py", line 587, in _check_open
    raise GPIODeviceClosed(str(e))
gpiozero.exc.GPIODeviceClosed: DigitalOutputDevice is closed or uninitialized
2025-04-16 17:07:57,254 [INFO] Starting homing procedure
2025-04-16 17:07:57,262 [INFO] Background threads started
2025-04-16 17:08:13,178 [INFO] Homing procedure complete and speed limits set
2025-04-16 17:08:13,179 [INFO] Homing complete
2025-04-16 17:09:43,851 [ERROR] Error in status_broadcast_loop
Traceback (most recent call last):
  File "/usr/lib/python3/dist-packages/gpiozero/devices.py", line 563, in _read
    return self._state_to_value(self.pin.state)
                                ^^^^^^^^^^^^^^
AttributeError: 'NoneType' object has no attribute 'state'

During handling of the above exception, another exception occurred:

Traceback (most recent call last):
  File "/usr/lib/python3/dist-packages/gpiozero/devices.py", line 584, in _check_open
    super()._check_open()
  File "/usr/lib/python3/dist-packages/gpiozero/devices.py", line 213, in _check_open
    raise DeviceClosed(
gpiozero.exc.DeviceClosed: OutputDevice is closed or uninitialized

During handling of the above exception, another exception occurred:

Traceback (most recent call last):
  File "/home/berke/Desktop/PurrfectSpray/Code/app.py", line 295, in status_broadcast_loop
    'cpu_temp': get_cpu_temp(),
             ^^^^^^^^^^^^^^^
  File "/usr/lib/python3/dist-packages/gpiozero/output_devices.py", line 121, in value
    return super().value
           ^^^^^^^^^^^^^
  File "/usr/lib/python3/dist-packages/gpiozero/devices.py", line 602, in value
    return self._read()
           ^^^^^^^^^^^^
  File "/usr/lib/python3/dist-packages/gpiozero/devices.py", line 565, in _read
    self._check_open()
  File "/usr/lib/python3/dist-packages/gpiozero/devices.py", line 587, in _check_open
    raise GPIODeviceClosed(str(e))
gpiozero.exc.GPIODeviceClosed: OutputDevice is closed or uninitialized
2025-04-16 17:09:44,000 [ERROR] Error in fan_loop
Traceback (most recent call last):
  File "/usr/lib/python3/dist-packages/gpiozero/output_devices.py", line 87, in _write
    self.pin.state = self._value_to_state(value)
    ^^^^^^^^^^^^^^
AttributeError: 'NoneType' object has no attribute 'state'

During handling of the above exception, another exception occurred:

Traceback (most recent call last):
  File "/usr/lib/python3/dist-packages/gpiozero/devices.py", line 584, in _check_open
    super()._check_open()
  File "/usr/lib/python3/dist-packages/gpiozero/devices.py", line 213, in _check_open
    raise DeviceClosed(
gpiozero.exc.DeviceClosed: OutputDevice is closed or uninitialized

During handling of the above exception, another exception occurred:

Traceback (most recent call last):
  File "/home/berke/Desktop/PurrfectSpray/Code/app.py", line 282, in fan_loop
    elif cpu_temp < 72:
        ^^^^^^^^^^^^^
  File "/usr/lib/python3/dist-packages/gpiozero/output_devices.py", line 102, in off
    self._write(False)
  File "/usr/lib/python3/dist-packages/gpiozero/output_devices.py", line 89, in _write
    self._check_open()
  File "/usr/lib/python3/dist-packages/gpiozero/devices.py", line 587, in _check_open
    raise GPIODeviceClosed(str(e))
gpiozero.exc.GPIODeviceClosed: OutputDevice is closed or uninitialized
2025-04-16 17:09:49,863 [INFO] Starting homing procedure
2025-04-16 17:09:49,873 [INFO] Background threads started
2025-04-16 17:10:02,382 [INFO] Homing procedure complete and speed limits set
2025-04-16 17:10:02,383 [INFO] Homing complete
2025-04-16 17:13:34,517 [ERROR] Error in status_broadcast_loop
Traceback (most recent call last):
  File "/usr/lib/python3/dist-packages/gpiozero/devices.py", line 563, in _read
    return self._state_to_value(self.pin.state)
                                ^^^^^^^^^^^^^^
AttributeError: 'NoneType' object has no attribute 'state'

During handling of the above exception, another exception occurred:

Traceback (most recent call last):
  File "/usr/lib/python3/dist-packages/gpiozero/devices.py", line 584, in _check_open
    super()._check_open()
  File "/usr/lib/python3/dist-packages/gpiozero/devices.py", line 213, in _check_open
    raise DeviceClosed(
gpiozero.exc.DeviceClosed: OutputDevice is closed or uninitialized

During handling of the above exception, another exception occurred:

Traceback (most recent call last):
  File "/home/berke/Desktop/PurrfectSpray/Code/app.py", line 296, in status_broadcast_loop
    'laser': laser_pin.value,
             ^^^^^^^^^^^^^^^
  File "/usr/lib/python3/dist-packages/gpiozero/output_devices.py", line 121, in value
    return super().value
           ^^^^^^^^^^^^^
  File "/usr/lib/python3/dist-packages/gpiozero/devices.py", line 602, in value
    return self._read()
           ^^^^^^^^^^^^
  File "/usr/lib/python3/dist-packages/gpiozero/devices.py", line 565, in _read
    self._check_open()
  File "/usr/lib/python3/dist-packages/gpiozero/devices.py", line 587, in _check_open
    raise GPIODeviceClosed(str(e))
gpiozero.exc.GPIODeviceClosed: OutputDevice is closed or uninitialized
2025-04-16 17:13:40,952 [INFO] Starting homing procedure
2025-04-16 17:13:40,959 [INFO] Background threads started
2025-04-16 17:13:55,803 [INFO] Homing procedure complete and speed limits set
2025-04-16 17:13:55,804 [INFO] Homing complete
2025-04-16 17:15:54,031 [ERROR] Error in fan_loop
Traceback (most recent call last):
  File "/usr/lib/python3/dist-packages/gpiozero/output_devices.py", line 87, in _write
    self.pin.state = self._value_to_state(value)
    ^^^^^^^^^^^^^^
AttributeError: 'NoneType' object has no attribute 'state'

During handling of the above exception, another exception occurred:

Traceback (most recent call last):
  File "/usr/lib/python3/dist-packages/gpiozero/devices.py", line 584, in _check_open
    super()._check_open()
  File "/usr/lib/python3/dist-packages/gpiozero/devices.py", line 213, in _check_open
    raise DeviceClosed(
gpiozero.exc.DeviceClosed: OutputDevice is closed or uninitialized

During handling of the above exception, another exception occurred:

Traceback (most recent call last):
  File "/home/berke/Desktop/PurrfectSpray/Code/app.py", line 283, in fan_loop
    elif cpu_temp < 72:
        ^^^^^^^^^^^^^
  File "/usr/lib/python3/dist-packages/gpiozero/output_devices.py", line 102, in off
    self._write(False)
  File "/usr/lib/python3/dist-packages/gpiozero/output_devices.py", line 89, in _write
    self._check_open()
  File "/usr/lib/python3/dist-packages/gpiozero/devices.py", line 587, in _check_open
    raise GPIODeviceClosed(str(e))
gpiozero.exc.GPIODeviceClosed: OutputDevice is closed or uninitialized
2025-04-16 17:15:54,031 [ERROR] Error in status_broadcast_loop
Traceback (most recent call last):
  File "/usr/lib/python3/dist-packages/gpiozero/devices.py", line 563, in _read
    return self._state_to_value(self.pin.state)
                                ^^^^^^^^^^^^^^
AttributeError: 'NoneType' object has no attribute 'state'

During handling of the above exception, another exception occurred:

Traceback (most recent call last):
  File "/usr/lib/python3/dist-packages/gpiozero/devices.py", line 584, in _check_open
    super()._check_open()
  File "/usr/lib/python3/dist-packages/gpiozero/devices.py", line 213, in _check_open
    raise DeviceClosed(
gpiozero.exc.DeviceClosed: OutputDevice is closed or uninitialized

During handling of the above exception, another exception occurred:

Traceback (most recent call last):
  File "/home/berke/Desktop/PurrfectSpray/Code/app.py", line 296, in status_broadcast_loop
    'cpu_temp': get_cpu_temp(),
             ^^^^^^^^^^^^^^^
  File "/usr/lib/python3/dist-packages/gpiozero/output_devices.py", line 121, in value
    return super().value
           ^^^^^^^^^^^^^
  File "/usr/lib/python3/dist-packages/gpiozero/devices.py", line 602, in value
    return self._read()
           ^^^^^^^^^^^^
  File "/usr/lib/python3/dist-packages/gpiozero/devices.py", line 565, in _read
    self._check_open()
  File "/usr/lib/python3/dist-packages/gpiozero/devices.py", line 587, in _check_open
    raise GPIODeviceClosed(str(e))
gpiozero.exc.GPIODeviceClosed: OutputDevice is closed or uninitialized
2025-04-16 17:16:00,242 [INFO] Starting homing procedure
2025-04-16 17:16:00,249 [INFO] Background threads started
2025-04-16 17:16:15,398 [INFO] Homing procedure complete and speed limits set
2025-04-16 17:16:15,400 [INFO] Homing complete
2025-04-16 17:18:20,452 [INFO] Starting homing procedure
2025-04-16 17:18:20,457 [INFO] Background threads started
2025-04-16 17:18:21,194 [ERROR] Error during homing_procedure
Traceback (most recent call last):
  File "/usr/lib/python3/dist-packages/gpiozero/devices.py", line 563, in _read
    return self._state_to_value(self.pin.state)
                                ^^^^^^^^^^^^^^
AttributeError: 'NoneType' object has no attribute 'state'

During handling of the above exception, another exception occurred:

Traceback (most recent call last):
  File "/usr/lib/python3/dist-packages/gpiozero/devices.py", line 584, in _check_open
    super()._check_open()
  File "/usr/lib/python3/dist-packages/gpiozero/devices.py", line 213, in _check_open
    raise DeviceClosed(
gpiozero.exc.DeviceClosed: DigitalInputDevice is closed or uninitialized

During handling of the above exception, another exception occurred:

Traceback (most recent call last):
  File "/home/berke/Desktop/PurrfectSpray/Code/motors.py", line 76, in homing_procedure
    home_motor(Motor1, hall_sensor_1, 1)
  File "/home/berke/Desktop/PurrfectSpray/Code/motors.py", line 41, in home_motor
    while read_sensor():
          ^^^^^^^^^^^^^
  File "/home/berke/Desktop/PurrfectSpray/Code/motors.py", line 36, in read_sensor
    return not hall_sensor.value
               ^^^^^^^^^^^^^^^^^
  File "/usr/lib/python3/dist-packages/gpiozero/devices.py", line 602, in value
    return self._read()
           ^^^^^^^^^^^^
  File "/usr/lib/python3/dist-packages/gpiozero/devices.py", line 565, in _read
    self._check_open()
  File "/usr/lib/python3/dist-packages/gpiozero/devices.py", line 587, in _check_open
    raise GPIODeviceClosed(str(e))
gpiozero.exc.GPIODeviceClosed: DigitalInputDevice is closed or uninitialized
2025-04-16 17:18:21,195 [INFO] Homing complete
2025-04-16 17:18:21,196 [ERROR] Error in motor_loop
Traceback (most recent call last):
  File "/usr/lib/python3/dist-packages/gpiozero/output_devices.py", line 87, in _write
    self.pin.state = self._value_to_state(value)
    ^^^^^^^^^^^^^^
AttributeError: 'NoneType' object has no attribute 'state'

During handling of the above exception, another exception occurred:

Traceback (most recent call last):
  File "/usr/lib/python3/dist-packages/gpiozero/devices.py", line 584, in _check_open
    super()._check_open()
  File "/usr/lib/python3/dist-packages/gpiozero/devices.py", line 213, in _check_open
    raise DeviceClosed(
gpiozero.exc.DeviceClosed: DigitalOutputDevice is closed or uninitialized

During handling of the above exception, another exception occurred:

Traceback (most recent call last):
  File "/home/berke/Desktop/PurrfectSpray/Code/app.py", line 266, in motor_loop
    Motor1.run()
  File "/home/berke/Desktop/PurrfectSpray/Code/AccelStepper.py", line 134, in run
    if self.run_speed():
       ^^^^^^^^^^^^^^^^
  File "/home/berke/Desktop/PurrfectSpray/Code/AccelStepper.py", line 75, in run_speed
    self.step(self._currentPos)
  File "/home/berke/Desktop/PurrfectSpray/Code/AccelStepper.py", line 180, in step
    self.step1(step)
  File "/home/berke/Desktop/PurrfectSpray/Code/AccelStepper.py", line 212, in step1
    self.set_output_pins(0b10 if self._direction else 0b00)
  File "/home/berke/Desktop/PurrfectSpray/Code/AccelStepper.py", line 203, in set_output_pins
    self._pins[i].off() if not self._pinInverted[i] else self._pins[i].on()
    ^^^^^^^^^^^^^^^^^^^
  File "/usr/lib/python3/dist-packages/gpiozero/output_devices.py", line 214, in off
    self._write(False)
  File "/usr/lib/python3/dist-packages/gpiozero/output_devices.py", line 89, in _write
    self._check_open()
  File "/usr/lib/python3/dist-packages/gpiozero/devices.py", line 587, in _check_open
    raise GPIODeviceClosed(str(e))
gpiozero.exc.GPIODeviceClosed: DigitalOutputDevice is closed or uninitialized
2025-04-16 17:18:21,214 [ERROR] Error in status_broadcast_loop
Traceback (most recent call last):
  File "/usr/lib/python3/dist-packages/gpiozero/devices.py", line 563, in _read
    return self._state_to_value(self.pin.state)
                                ^^^^^^^^^^^^^^
AttributeError: 'NoneType' object has no attribute 'state'

During handling of the above exception, another exception occurred:

Traceback (most recent call last):
  File "/usr/lib/python3/dist-packages/gpiozero/devices.py", line 584, in _check_open
    super()._check_open()
  File "/usr/lib/python3/dist-packages/gpiozero/devices.py", line 213, in _check_open
    raise DeviceClosed(
gpiozero.exc.DeviceClosed: OutputDevice is closed or uninitialized

During handling of the above exception, another exception occurred:

Traceback (most recent call last):
  File "/home/berke/Desktop/PurrfectSpray/Code/app.py", line 298, in status_broadcast_loop
    'laser': laser_pin.value,
             ^^^^^^^^^^^^^^^
  File "/usr/lib/python3/dist-packages/gpiozero/output_devices.py", line 121, in value
    return super().value
           ^^^^^^^^^^^^^
  File "/usr/lib/python3/dist-packages/gpiozero/devices.py", line 602, in value
    return self._read()
           ^^^^^^^^^^^^
  File "/usr/lib/python3/dist-packages/gpiozero/devices.py", line 565, in _read
    self._check_open()
  File "/usr/lib/python3/dist-packages/gpiozero/devices.py", line 587, in _check_open
    raise GPIODeviceClosed(str(e))
gpiozero.exc.GPIODeviceClosed: OutputDevice is closed or uninitialized
2025-04-16 17:18:35,955 [INFO] Starting homing procedure
2025-04-16 17:18:35,964 [INFO] Background threads started
2025-04-16 17:18:50,026 [INFO] Homing procedure complete and speed limits set
2025-04-16 17:18:50,027 [INFO] Homing complete
2025-04-16 17:19:59,034 [ERROR] Error in status_broadcast_loop
Traceback (most recent call last):
  File "/usr/lib/python3/dist-packages/gpiozero/devices.py", line 563, in _read
    return self._state_to_value(self.pin.state)
                                ^^^^^^^^^^^^^^
AttributeError: 'NoneType' object has no attribute 'state'

During handling of the above exception, another exception occurred:

Traceback (most recent call last):
  File "/usr/lib/python3/dist-packages/gpiozero/devices.py", line 584, in _check_open
    super()._check_open()
  File "/usr/lib/python3/dist-packages/gpiozero/devices.py", line 213, in _check_open
    raise DeviceClosed(
gpiozero.exc.DeviceClosed: OutputDevice is closed or uninitialized

During handling of the above exception, another exception occurred:

Traceback (most recent call last):
  File "/home/berke/Desktop/PurrfectSpray/Code/app.py", line 299, in status_broadcast_loop
    'homing': homing_complete,
             ^^^^^^^^^^^^^^^
  File "/usr/lib/python3/dist-packages/gpiozero/output_devices.py", line 121, in value
    return super().value
           ^^^^^^^^^^^^^
  File "/usr/lib/python3/dist-packages/gpiozero/devices.py", line 602, in value
    return self._read()
           ^^^^^^^^^^^^
  File "/usr/lib/python3/dist-packages/gpiozero/devices.py", line 565, in _read
    self._check_open()
  File "/usr/lib/python3/dist-packages/gpiozero/devices.py", line 587, in _check_open
    raise GPIODeviceClosed(str(e))
gpiozero.exc.GPIODeviceClosed: OutputDevice is closed or uninitialized
2025-04-16 17:20:06,303 [INFO] Starting homing procedure
2025-04-16 17:20:06,311 [INFO] Background threads started
2025-04-16 17:20:21,012 [INFO] Homing procedure complete and speed limits set
2025-04-16 17:20:21,014 [INFO] Homing complete
2025-04-16 17:21:09,109 [ERROR] Error in status_broadcast_loop
Traceback (most recent call last):
  File "/usr/lib/python3/dist-packages/gpiozero/devices.py", line 563, in _read
    return self._state_to_value(self.pin.state)
                                ^^^^^^^^^^^^^^
AttributeError: 'NoneType' object has no attribute 'state'

During handling of the above exception, another exception occurred:

Traceback (most recent call last):
  File "/usr/lib/python3/dist-packages/gpiozero/devices.py", line 584, in _check_open
    super()._check_open()
  File "/usr/lib/python3/dist-packages/gpiozero/devices.py", line 213, in _check_open
    raise DeviceClosed(
gpiozero.exc.DeviceClosed: OutputDevice is closed or uninitialized

During handling of the above exception, another exception occurred:

Traceback (most recent call last):
  File "/home/berke/Desktop/PurrfectSpray/Code/app.py", line 298, in status_broadcast_loop
    'motor2': Motor2.current_position() * DEGREES_PER_STEP_2,
             ^^^^^^^^^^^^^^^
  File "/usr/lib/python3/dist-packages/gpiozero/output_devices.py", line 121, in value
    return super().value
           ^^^^^^^^^^^^^
  File "/usr/lib/python3/dist-packages/gpiozero/devices.py", line 602, in value
    return self._read()
           ^^^^^^^^^^^^
  File "/usr/lib/python3/dist-packages/gpiozero/devices.py", line 565, in _read
    self._check_open()
  File "/usr/lib/python3/dist-packages/gpiozero/devices.py", line 587, in _check_open
    raise GPIODeviceClosed(str(e))
gpiozero.exc.GPIODeviceClosed: OutputDevice is closed or uninitialized
2025-04-16 17:21:17,212 [INFO] Starting homing procedure
2025-04-16 17:21:17,220 [INFO] Background threads started
2025-04-16 17:21:31,963 [INFO] Homing procedure complete and speed limits set
2025-04-16 17:21:31,964 [INFO] Homing complete
2025-04-16 17:23:18,765 [ERROR] Error in status_broadcast_loop
Traceback (most recent call last):
  File "/usr/lib/python3/dist-packages/gpiozero/devices.py", line 563, in _read
    return self._state_to_value(self.pin.state)
                                ^^^^^^^^^^^^^^
AttributeError: 'NoneType' object has no attribute 'state'

During handling of the above exception, another exception occurred:

Traceback (most recent call last):
  File "/usr/lib/python3/dist-packages/gpiozero/devices.py", line 584, in _check_open
    super()._check_open()
  File "/usr/lib/python3/dist-packages/gpiozero/devices.py", line 213, in _check_open
    raise DeviceClosed(
gpiozero.exc.DeviceClosed: OutputDevice is closed or uninitialized

During handling of the above exception, another exception occurred:

Traceback (most recent call last):
  File "/home/berke/Desktop/PurrfectSpray/Code/app.py", line 300, in status_broadcast_loop
    'laser': laser_pin.value,
             ^^^^^^^^^^^^^^^
  File "/usr/lib/python3/dist-packages/gpiozero/output_devices.py", line 121, in value
    return super().value
           ^^^^^^^^^^^^^
  File "/usr/lib/python3/dist-packages/gpiozero/devices.py", line 602, in value
    return self._read()
           ^^^^^^^^^^^^
  File "/usr/lib/python3/dist-packages/gpiozero/devices.py", line 565, in _read
    self._check_open()
  File "/usr/lib/python3/dist-packages/gpiozero/devices.py", line 587, in _check_open
    raise GPIODeviceClosed(str(e))
gpiozero.exc.GPIODeviceClosed: OutputDevice is closed or uninitialized
2025-04-16 17:23:25,587 [INFO] Starting homing procedure
2025-04-16 17:23:25,595 [INFO] Background threads started
2025-04-16 17:23:40,262 [INFO] Homing procedure complete and speed limits set
2025-04-16 17:23:40,263 [INFO] Homing complete
2025-04-16 17:26:33,915 [ERROR] Error in fan_loop
Traceback (most recent call last):
  File "/usr/lib/python3/dist-packages/gpiozero/output_devices.py", line 87, in _write
    self.pin.state = self._value_to_state(value)
    ^^^^^^^^^^^^^^
AttributeError: 'NoneType' object has no attribute 'state'

During handling of the above exception, another exception occurred:

Traceback (most recent call last):
  File "/usr/lib/python3/dist-packages/gpiozero/devices.py", line 584, in _check_open
    super()._check_open()
  File "/usr/lib/python3/dist-packages/gpiozero/devices.py", line 213, in _check_open
    raise DeviceClosed(
gpiozero.exc.DeviceClosed: OutputDevice is closed or uninitialized

During handling of the above exception, another exception occurred:

Traceback (most recent call last):
  File "/home/berke/Desktop/PurrfectSpray/Code/app.py", line 288, in fan_loop
    try:
         
  File "/usr/lib/python3/dist-packages/gpiozero/output_devices.py", line 102, in off
    self._write(False)
  File "/usr/lib/python3/dist-packages/gpiozero/output_devices.py", line 89, in _write
    self._check_open()
  File "/usr/lib/python3/dist-packages/gpiozero/devices.py", line 587, in _check_open
    raise GPIODeviceClosed(str(e))
gpiozero.exc.GPIODeviceClosed: OutputDevice is closed or uninitialized
2025-04-16 17:26:33,921 [ERROR] Error in status_broadcast_loop
Traceback (most recent call last):
  File "/usr/lib/python3/dist-packages/gpiozero/devices.py", line 563, in _read
    return self._state_to_value(self.pin.state)
                                ^^^^^^^^^^^^^^
AttributeError: 'NoneType' object has no attribute 'state'

During handling of the above exception, another exception occurred:

Traceback (most recent call last):
  File "/usr/lib/python3/dist-packages/gpiozero/devices.py", line 584, in _check_open
    super()._check_open()
  File "/usr/lib/python3/dist-packages/gpiozero/devices.py", line 213, in _check_open
    raise DeviceClosed(
gpiozero.exc.DeviceClosed: OutputDevice is closed or uninitialized

During handling of the above exception, another exception occurred:

Traceback (most recent call last):
  File "/home/berke/Desktop/PurrfectSpray/Code/app.py", line 301, in status_broadcast_loop
    try:
         
  File "/usr/lib/python3/dist-packages/gpiozero/output_devices.py", line 121, in value
    return super().value
           ^^^^^^^^^^^^^
  File "/usr/lib/python3/dist-packages/gpiozero/devices.py", line 602, in value
    return self._read()
           ^^^^^^^^^^^^
  File "/usr/lib/python3/dist-packages/gpiozero/devices.py", line 565, in _read
    self._check_open()
  File "/usr/lib/python3/dist-packages/gpiozero/devices.py", line 587, in _check_open
    raise GPIODeviceClosed(str(e))
gpiozero.exc.GPIODeviceClosed: OutputDevice is closed or uninitialized
2025-04-16 17:26:41,107 [INFO] Starting homing procedure
2025-04-16 17:26:41,115 [INFO] Background threads started
2025-04-16 17:26:55,771 [INFO] Homing procedure complete and speed limits set
2025-04-16 17:26:55,783 [INFO] Homing complete
2025-04-16 17:29:12,755 [INFO] Starting homing procedure
2025-04-16 17:29:12,762 [INFO] Background threads started
2025-04-16 17:29:27,424 [INFO] Homing procedure complete and speed limits set
2025-04-16 17:29:27,424 [INFO] Homing complete
2025-04-16 17:32:05,821 [ERROR] Error in status_broadcast_loop
Traceback (most recent call last):
  File "/usr/lib/python3/dist-packages/gpiozero/devices.py", line 563, in _read
    return self._state_to_value(self.pin.state)
                                ^^^^^^^^^^^^^^
AttributeError: 'NoneType' object has no attribute 'state'

During handling of the above exception, another exception occurred:

Traceback (most recent call last):
  File "/usr/lib/python3/dist-packages/gpiozero/devices.py", line 584, in _check_open
    super()._check_open()
  File "/usr/lib/python3/dist-packages/gpiozero/devices.py", line 213, in _check_open
    raise DeviceClosed(
gpiozero.exc.DeviceClosed: OutputDevice is closed or uninitialized

During handling of the above exception, another exception occurred:

Traceback (most recent call last):
  File "/home/berke/Desktop/PurrfectSpray/Code/app.py", line 307, in status_broadcast_loop
    'laser': laser_pin.value,
             ^^^^^^^^^^^^^^^
  File "/usr/lib/python3/dist-packages/gpiozero/output_devices.py", line 121, in value
    return super().value
           ^^^^^^^^^^^^^
  File "/usr/lib/python3/dist-packages/gpiozero/devices.py", line 602, in value
    return self._read()
           ^^^^^^^^^^^^
  File "/usr/lib/python3/dist-packages/gpiozero/devices.py", line 565, in _read
    self._check_open()
  File "/usr/lib/python3/dist-packages/gpiozero/devices.py", line 587, in _check_open
    raise GPIODeviceClosed(str(e))
gpiozero.exc.GPIODeviceClosed: OutputDevice is closed or uninitialized
2025-04-16 17:32:16,625 [INFO] Starting homing procedure
2025-04-16 17:32:16,633 [INFO] Background threads started
2025-04-16 17:32:31,462 [INFO] Homing procedure complete and speed limits set
2025-04-16 17:32:31,463 [INFO] Homing complete
2025-04-16 17:37:21,321 [INFO] Starting homing procedure
2025-04-16 17:37:21,328 [INFO] Background threads started
2025-04-16 17:37:35,922 [INFO] Homing procedure complete and speed limits set
2025-04-16 17:37:35,924 [INFO] Homing complete
2025-04-16 17:41:05,725 [INFO] Starting homing procedure
2025-04-16 17:41:05,730 [INFO] Background threads started
2025-04-16 17:41:20,242 [INFO] Homing procedure complete and speed limits set
2025-04-16 17:41:20,243 [INFO] Homing complete
2025-04-16 17:56:23,190 [ERROR] Error in status_broadcast_loop
Traceback (most recent call last):
  File "/usr/lib/python3/dist-packages/gpiozero/devices.py", line 563, in _read
    return self._state_to_value(self.pin.state)
                                ^^^^^^^^^^^^^^
AttributeError: 'NoneType' object has no attribute 'state'

During handling of the above exception, another exception occurred:

Traceback (most recent call last):
  File "/usr/lib/python3/dist-packages/gpiozero/devices.py", line 584, in _check_open
    super()._check_open()
  File "/usr/lib/python3/dist-packages/gpiozero/devices.py", line 213, in _check_open
    raise DeviceClosed(
gpiozero.exc.DeviceClosed: OutputDevice is closed or uninitialized

During handling of the above exception, another exception occurred:

Traceback (most recent call last):
  File "/home/berke/Desktop/PurrfectSpray/Code/app.py", line 320, in status_broadcast_loop
    'sensor2': not hall_sensor_2.value
             ^^^^^^^^^^^^^^^
  File "/usr/lib/python3/dist-packages/gpiozero/output_devices.py", line 121, in value
    return super().value
           ^^^^^^^^^^^^^
  File "/usr/lib/python3/dist-packages/gpiozero/devices.py", line 602, in value
    return self._read()
           ^^^^^^^^^^^^
  File "/usr/lib/python3/dist-packages/gpiozero/devices.py", line 565, in _read
    self._check_open()
  File "/usr/lib/python3/dist-packages/gpiozero/devices.py", line 587, in _check_open
    raise GPIODeviceClosed(str(e))
gpiozero.exc.GPIODeviceClosed: OutputDevice is closed or uninitialized
2025-04-16 18:16:10,966 [INFO] Starting homing procedure
2025-04-16 18:16:10,974 [INFO] Background threads started
2025-04-16 18:16:17,882 [ERROR] Error during homing_procedure
Traceback (most recent call last):
  File "/usr/lib/python3/dist-packages/gpiozero/devices.py", line 563, in _read
    return self._state_to_value(self.pin.state)
                                ^^^^^^^^^^^^^^
AttributeError: 'NoneType' object has no attribute 'state'

During handling of the above exception, another exception occurred:

Traceback (most recent call last):
  File "/usr/lib/python3/dist-packages/gpiozero/devices.py", line 584, in _check_open
    super()._check_open()
  File "/usr/lib/python3/dist-packages/gpiozero/devices.py", line 213, in _check_open
    raise DeviceClosed(
gpiozero.exc.DeviceClosed: DigitalInputDevice is closed or uninitialized

During handling of the above exception, another exception occurred:

Traceback (most recent call last):
  File "/home/berke/Desktop/PurrfectSpray/Code/motors.py", line 76, in homing_procedure
    home_motor(Motor1, hall_sensor_1, 1)
  File "/home/berke/Desktop/PurrfectSpray/Code/motors.py", line 54, in home_motor
    while read_sensor():
          ^^^^^^^^^^^^^
  File "/home/berke/Desktop/PurrfectSpray/Code/motors.py", line 36, in read_sensor
    return not hall_sensor.value
               ^^^^^^^^^^^^^^^^^
  File "/usr/lib/python3/dist-packages/gpiozero/devices.py", line 602, in value
    return self._read()
           ^^^^^^^^^^^^
  File "/usr/lib/python3/dist-packages/gpiozero/devices.py", line 565, in _read
    self._check_open()
  File "/usr/lib/python3/dist-packages/gpiozero/devices.py", line 587, in _check_open
    raise GPIODeviceClosed(str(e))
gpiozero.exc.GPIODeviceClosed: DigitalInputDevice is closed or uninitialized
2025-04-16 18:16:17,886 [INFO] Homing complete
2025-04-16 18:16:17,887 [ERROR] Error in motor_loop
Traceback (most recent call last):
  File "/usr/lib/python3/dist-packages/gpiozero/output_devices.py", line 87, in _write
    self.pin.state = self._value_to_state(value)
    ^^^^^^^^^^^^^^
AttributeError: 'NoneType' object has no attribute 'state'

During handling of the above exception, another exception occurred:

Traceback (most recent call last):
  File "/usr/lib/python3/dist-packages/gpiozero/devices.py", line 584, in _check_open
    super()._check_open()
  File "/usr/lib/python3/dist-packages/gpiozero/devices.py", line 213, in _check_open
    raise DeviceClosed(
gpiozero.exc.DeviceClosed: DigitalOutputDevice is closed or uninitialized

During handling of the above exception, another exception occurred:

Traceback (most recent call last):
  File "/home/berke/Desktop/PurrfectSpray/Code/app.py", line 240, in motor_loop
    Motor1.run()
  File "/home/berke/Desktop/PurrfectSpray/Code/AccelStepper.py", line 134, in run
    if self.run_speed():
       ^^^^^^^^^^^^^^^^
  File "/home/berke/Desktop/PurrfectSpray/Code/AccelStepper.py", line 75, in run_speed
    self.step(self._currentPos)
  File "/home/berke/Desktop/PurrfectSpray/Code/AccelStepper.py", line 180, in step
    self.step1(step)
  File "/home/berke/Desktop/PurrfectSpray/Code/AccelStepper.py", line 212, in step1
    self.set_output_pins(0b10 if self._direction else 0b00)
  File "/home/berke/Desktop/PurrfectSpray/Code/AccelStepper.py", line 203, in set_output_pins
    self._pins[i].off() if not self._pinInverted[i] else self._pins[i].on()
    ^^^^^^^^^^^^^^^^^^^
  File "/usr/lib/python3/dist-packages/gpiozero/output_devices.py", line 214, in off
    self._write(False)
  File "/usr/lib/python3/dist-packages/gpiozero/output_devices.py", line 89, in _write
    self._check_open()
  File "/usr/lib/python3/dist-packages/gpiozero/devices.py", line 587, in _check_open
    raise GPIODeviceClosed(str(e))
gpiozero.exc.GPIODeviceClosed: DigitalOutputDevice is closed or uninitialized
2025-04-16 18:16:18,009 [ERROR] Error in fan_loop
Traceback (most recent call last):
  File "/usr/lib/python3/dist-packages/gpiozero/output_devices.py", line 87, in _write
    self.pin.state = self._value_to_state(value)
    ^^^^^^^^^^^^^^
AttributeError: 'NoneType' object has no attribute 'state'

During handling of the above exception, another exception occurred:

Traceback (most recent call last):
  File "/usr/lib/python3/dist-packages/gpiozero/devices.py", line 584, in _check_open
    super()._check_open()
  File "/usr/lib/python3/dist-packages/gpiozero/devices.py", line 213, in _check_open
    raise DeviceClosed(
gpiozero.exc.DeviceClosed: OutputDevice is closed or uninitialized

During handling of the above exception, another exception occurred:

Traceback (most recent call last):
  File "/home/berke/Desktop/PurrfectSpray/Code/app.py", line 259, in fan_loop
    fan_pin.off()
  File "/usr/lib/python3/dist-packages/gpiozero/output_devices.py", line 102, in off
    self._write(False)
  File "/usr/lib/python3/dist-packages/gpiozero/output_devices.py", line 89, in _write
    self._check_open()
  File "/usr/lib/python3/dist-packages/gpiozero/devices.py", line 587, in _check_open
    raise GPIODeviceClosed(str(e))
gpiozero.exc.GPIODeviceClosed: OutputDevice is closed or uninitialized
2025-04-16 18:16:29,540 [INFO] Starting homing procedure
2025-04-16 18:16:29,546 [INFO] Background threads started
2025-04-16 18:16:41,988 [INFO] Homing procedure complete and speed limits set
2025-04-16 18:16:41,988 [INFO] Homing complete
2025-04-16 18:46:01,344 [INFO] Starting homing procedure
2025-04-16 18:46:01,351 [INFO] Background threads started
2025-04-16 18:46:15,761 [INFO] Homing procedure complete and speed limits set
2025-04-16 18:46:15,762 [INFO] Homing complete
2025-04-16 18:48:42,448 [ERROR] Error in status_broadcast_loop
Traceback (most recent call last):
  File "/usr/lib/python3/dist-packages/gpiozero/devices.py", line 563, in _read
    return self._state_to_value(self.pin.state)
                                ^^^^^^^^^^^^^^
AttributeError: 'NoneType' object has no attribute 'state'

During handling of the above exception, another exception occurred:

Traceback (most recent call last):
  File "/usr/lib/python3/dist-packages/gpiozero/devices.py", line 584, in _check_open
    super()._check_open()
  File "/usr/lib/python3/dist-packages/gpiozero/devices.py", line 213, in _check_open
    raise DeviceClosed(
gpiozero.exc.DeviceClosed: OutputDevice is closed or uninitialized

During handling of the above exception, another exception occurred:

Traceback (most recent call last):
  File "/home/berke/Desktop/PurrfectSpray/Code/app.py", line 272, in status_broadcast_loop
    'laser': laser_pin.value,
             ^^^^^^^^^^^^^^^
  File "/usr/lib/python3/dist-packages/gpiozero/output_devices.py", line 121, in value
    return super().value
           ^^^^^^^^^^^^^
  File "/usr/lib/python3/dist-packages/gpiozero/devices.py", line 602, in value
    return self._read()
           ^^^^^^^^^^^^
  File "/usr/lib/python3/dist-packages/gpiozero/devices.py", line 565, in _read
    self._check_open()
  File "/usr/lib/python3/dist-packages/gpiozero/devices.py", line 587, in _check_open
    raise GPIODeviceClosed(str(e))
gpiozero.exc.GPIODeviceClosed: OutputDevice is closed or uninitialized
2025-04-16 18:48:51,092 [INFO] Starting homing procedure
2025-04-16 18:48:51,098 [INFO] Background threads started
2025-04-16 18:49:05,531 [INFO] Homing procedure complete and speed limits set
2025-04-16 18:49:05,532 [INFO] Homing complete
2025-04-16 18:54:55,892 [ERROR] Error in fan_loop
Traceback (most recent call last):
  File "/usr/lib/python3/dist-packages/gpiozero/output_devices.py", line 87, in _write
    self.pin.state = self._value_to_state(value)
    ^^^^^^^^^^^^^^
AttributeError: 'NoneType' object has no attribute 'state'

During handling of the above exception, another exception occurred:

Traceback (most recent call last):
  File "/usr/lib/python3/dist-packages/gpiozero/devices.py", line 584, in _check_open
    super()._check_open()
  File "/usr/lib/python3/dist-packages/gpiozero/devices.py", line 213, in _check_open
    raise DeviceClosed(
gpiozero.exc.DeviceClosed: OutputDevice is closed or uninitialized

During handling of the above exception, another exception occurred:

Traceback (most recent call last):
  File "/home/berke/Desktop/PurrfectSpray/Code/app.py", line 259, in fan_loop
    fan_pin.off()
  File "/usr/lib/python3/dist-packages/gpiozero/output_devices.py", line 102, in off
    self._write(False)
  File "/usr/lib/python3/dist-packages/gpiozero/output_devices.py", line 89, in _write
    self._check_open()
  File "/usr/lib/python3/dist-packages/gpiozero/devices.py", line 587, in _check_open
    raise GPIODeviceClosed(str(e))
gpiozero.exc.GPIODeviceClosed: OutputDevice is closed or uninitialized
2025-04-16 18:54:55,982 [ERROR] Error in status_broadcast_loop
Traceback (most recent call last):
  File "/usr/lib/python3/dist-packages/gpiozero/devices.py", line 563, in _read
    return self._state_to_value(self.pin.state)
                                ^^^^^^^^^^^^^^
AttributeError: 'NoneType' object has no attribute 'state'

During handling of the above exception, another exception occurred:

Traceback (most recent call last):
  File "/usr/lib/python3/dist-packages/gpiozero/devices.py", line 584, in _check_open
    super()._check_open()
  File "/usr/lib/python3/dist-packages/gpiozero/devices.py", line 213, in _check_open
    raise DeviceClosed(
gpiozero.exc.DeviceClosed: OutputDevice is closed or uninitialized

During handling of the above exception, another exception occurred:

Traceback (most recent call last):
  File "/home/berke/Desktop/PurrfectSpray/Code/app.py", line 272, in status_broadcast_loop
    'laser': laser_pin.value,
             ^^^^^^^^^^^^^^^
  File "/usr/lib/python3/dist-packages/gpiozero/output_devices.py", line 121, in value
    return super().value
           ^^^^^^^^^^^^^
  File "/usr/lib/python3/dist-packages/gpiozero/devices.py", line 602, in value
    return self._read()
           ^^^^^^^^^^^^
  File "/usr/lib/python3/dist-packages/gpiozero/devices.py", line 565, in _read
    self._check_open()
  File "/usr/lib/python3/dist-packages/gpiozero/devices.py", line 587, in _check_open
    raise GPIODeviceClosed(str(e))
gpiozero.exc.GPIODeviceClosed: OutputDevice is closed or uninitialized
2025-04-16 18:55:02,693 [INFO] Starting homing procedure
2025-04-16 18:55:02,702 [INFO] Background threads started
2025-04-16 18:55:17,375 [INFO] Homing procedure complete and speed limits set
2025-04-16 18:55:17,377 [INFO] Homing complete
2025-04-16 19:01:49,547 [ERROR] Error in status_broadcast_loop
Traceback (most recent call last):
  File "/usr/lib/python3/dist-packages/gpiozero/devices.py", line 563, in _read
    return self._state_to_value(self.pin.state)
                                ^^^^^^^^^^^^^^
AttributeError: 'NoneType' object has no attribute 'state'

During handling of the above exception, another exception occurred:

Traceback (most recent call last):
  File "/usr/lib/python3/dist-packages/gpiozero/devices.py", line 584, in _check_open
    super()._check_open()
  File "/usr/lib/python3/dist-packages/gpiozero/devices.py", line 213, in _check_open
    raise DeviceClosed(
gpiozero.exc.DeviceClosed: OutputDevice is closed or uninitialized

During handling of the above exception, another exception occurred:

Traceback (most recent call last):
  File "/home/berke/Desktop/PurrfectSpray/Code/app.py", line 272, in status_broadcast_loop
    'laser': laser_pin.value,
             ^^^^^^^^^^^^^^^
  File "/usr/lib/python3/dist-packages/gpiozero/output_devices.py", line 121, in value
    return super().value
           ^^^^^^^^^^^^^
  File "/usr/lib/python3/dist-packages/gpiozero/devices.py", line 602, in value
    return self._read()
           ^^^^^^^^^^^^
  File "/usr/lib/python3/dist-packages/gpiozero/devices.py", line 565, in _read
    self._check_open()
  File "/usr/lib/python3/dist-packages/gpiozero/devices.py", line 587, in _check_open
    raise GPIODeviceClosed(str(e))
gpiozero.exc.GPIODeviceClosed: OutputDevice is closed or uninitialized
2025-04-16 19:01:49,600 [ERROR] Error in fan_loop
Traceback (most recent call last):
  File "/usr/lib/python3/dist-packages/gpiozero/output_devices.py", line 87, in _write
    self.pin.state = self._value_to_state(value)
    ^^^^^^^^^^^^^^
AttributeError: 'NoneType' object has no attribute 'state'

During handling of the above exception, another exception occurred:

Traceback (most recent call last):
  File "/usr/lib/python3/dist-packages/gpiozero/devices.py", line 584, in _check_open
    super()._check_open()
  File "/usr/lib/python3/dist-packages/gpiozero/devices.py", line 213, in _check_open
    raise DeviceClosed(
gpiozero.exc.DeviceClosed: OutputDevice is closed or uninitialized

During handling of the above exception, another exception occurred:

Traceback (most recent call last):
  File "/home/berke/Desktop/PurrfectSpray/Code/app.py", line 259, in fan_loop
    fan_pin.off()
  File "/usr/lib/python3/dist-packages/gpiozero/output_devices.py", line 102, in off
    self._write(False)
  File "/usr/lib/python3/dist-packages/gpiozero/output_devices.py", line 89, in _write
    self._check_open()
  File "/usr/lib/python3/dist-packages/gpiozero/devices.py", line 587, in _check_open
    raise GPIODeviceClosed(str(e))
gpiozero.exc.GPIODeviceClosed: OutputDevice is closed or uninitialized
2025-04-16 19:01:59,649 [INFO] Starting homing procedure
2025-04-16 19:01:59,655 [INFO] Background threads started
2025-04-16 19:02:14,098 [INFO] Homing procedure complete and speed limits set
2025-04-16 19:02:14,098 [INFO] Homing complete
2025-04-16 19:12:17,260 [ERROR] Error in status_broadcast_loop
Traceback (most recent call last):
  File "/usr/lib/python3/dist-packages/gpiozero/devices.py", line 563, in _read
    return self._state_to_value(self.pin.state)
                                ^^^^^^^^^^^^^^
AttributeError: 'NoneType' object has no attribute 'state'

During handling of the above exception, another exception occurred:

Traceback (most recent call last):
  File "/usr/lib/python3/dist-packages/gpiozero/devices.py", line 584, in _check_open
    super()._check_open()
  File "/usr/lib/python3/dist-packages/gpiozero/devices.py", line 213, in _check_open
    raise DeviceClosed(
gpiozero.exc.DeviceClosed: OutputDevice is closed or uninitialized

During handling of the above exception, another exception occurred:

Traceback (most recent call last):
  File "/home/berke/Desktop/PurrfectSpray/Code/app.py", line 272, in status_broadcast_loop
    'laser': laser_pin.value,
             ^^^^^^^^^^^^^^^
  File "/usr/lib/python3/dist-packages/gpiozero/output_devices.py", line 121, in value
    return super().value
           ^^^^^^^^^^^^^
  File "/usr/lib/python3/dist-packages/gpiozero/devices.py", line 602, in value
    return self._read()
           ^^^^^^^^^^^^
  File "/usr/lib/python3/dist-packages/gpiozero/devices.py", line 565, in _read
    self._check_open()
  File "/usr/lib/python3/dist-packages/gpiozero/devices.py", line 587, in _check_open
    raise GPIODeviceClosed(str(e))
gpiozero.exc.GPIODeviceClosed: OutputDevice is closed or uninitialized
2025-04-16 19:12:17,323 [ERROR] Error in fan_loop
Traceback (most recent call last):
  File "/usr/lib/python3/dist-packages/gpiozero/output_devices.py", line 87, in _write
    self.pin.state = self._value_to_state(value)
    ^^^^^^^^^^^^^^
AttributeError: 'NoneType' object has no attribute 'state'

During handling of the above exception, another exception occurred:

Traceback (most recent call last):
  File "/usr/lib/python3/dist-packages/gpiozero/devices.py", line 584, in _check_open
    super()._check_open()
  File "/usr/lib/python3/dist-packages/gpiozero/devices.py", line 213, in _check_open
    raise DeviceClosed(
gpiozero.exc.DeviceClosed: OutputDevice is closed or uninitialized

During handling of the above exception, another exception occurred:

Traceback (most recent call last):
  File "/home/berke/Desktop/PurrfectSpray/Code/app.py", line 259, in fan_loop
    fan_pin.off()
  File "/usr/lib/python3/dist-packages/gpiozero/output_devices.py", line 102, in off
    self._write(False)
  File "/usr/lib/python3/dist-packages/gpiozero/output_devices.py", line 89, in _write
    self._check_open()
  File "/usr/lib/python3/dist-packages/gpiozero/devices.py", line 587, in _check_open
    raise GPIODeviceClosed(str(e))
gpiozero.exc.GPIODeviceClosed: OutputDevice is closed or uninitialized
2025-04-16 19:12:23,997 [INFO] Starting homing procedure
2025-04-16 19:12:24,003 [INFO] Background threads started
2025-04-16 19:12:41,586 [INFO] Homing procedure complete and speed limits set
2025-04-16 19:12:41,588 [INFO] Homing complete
2025-04-16 19:27:36,954 [ERROR] Error in status_broadcast_loop
Traceback (most recent call last):
  File "/usr/lib/python3/dist-packages/gpiozero/devices.py", line 563, in _read
    return self._state_to_value(self.pin.state)
                                ^^^^^^^^^^^^^^
AttributeError: 'NoneType' object has no attribute 'state'

During handling of the above exception, another exception occurred:

Traceback (most recent call last):
  File "/usr/lib/python3/dist-packages/gpiozero/devices.py", line 584, in _check_open
    super()._check_open()
  File "/usr/lib/python3/dist-packages/gpiozero/devices.py", line 213, in _check_open
    raise DeviceClosed(
gpiozero.exc.DeviceClosed: OutputDevice is closed or uninitialized

During handling of the above exception, another exception occurred:

Traceback (most recent call last):
  File "/home/berke/Desktop/PurrfectSpray/Code/app.py", line 272, in status_broadcast_loop
    'homing': homing_complete,
             ^^^^^^^^^^^^^^^
  File "/usr/lib/python3/dist-packages/gpiozero/output_devices.py", line 121, in value
    return super().value
           ^^^^^^^^^^^^^
  File "/usr/lib/python3/dist-packages/gpiozero/devices.py", line 602, in value
    return self._read()
           ^^^^^^^^^^^^
  File "/usr/lib/python3/dist-packages/gpiozero/devices.py", line 565, in _read
    self._check_open()
  File "/usr/lib/python3/dist-packages/gpiozero/devices.py", line 587, in _check_open
    raise GPIODeviceClosed(str(e))
gpiozero.exc.GPIODeviceClosed: OutputDevice is closed or uninitialized
2025-04-16 19:27:44,300 [INFO] Starting homing procedure
2025-04-16 19:27:44,308 [INFO] Background threads started
2025-04-16 19:28:00,006 [INFO] Homing procedure complete and speed limits set
2025-04-16 19:28:00,007 [INFO] Homing complete
2025-04-16 19:32:41,784 [INFO] Starting homing procedure
2025-04-16 19:32:41,792 [INFO] Background threads started
2025-04-16 19:33:00,703 [INFO] Homing procedure complete and speed limits set
2025-04-16 19:33:00,703 [INFO] Homing complete
2025-04-16 19:33:48,644 [ERROR] Error in status_broadcast_loop
Traceback (most recent call last):
  File "/usr/lib/python3/dist-packages/gpiozero/devices.py", line 563, in _read
    return self._state_to_value(self.pin.state)
                                ^^^^^^^^^^^^^^
AttributeError: 'NoneType' object has no attribute 'state'

During handling of the above exception, another exception occurred:

Traceback (most recent call last):
  File "/usr/lib/python3/dist-packages/gpiozero/devices.py", line 584, in _check_open
    super()._check_open()
  File "/usr/lib/python3/dist-packages/gpiozero/devices.py", line 213, in _check_open
    raise DeviceClosed(
gpiozero.exc.DeviceClosed: OutputDevice is closed or uninitialized

During handling of the above exception, another exception occurred:

Traceback (most recent call last):
  File "/home/berke/Desktop/PurrfectSpray/Code/app.py", line 271, in status_broadcast_loop
    'laser': laser_pin.value,
             ^^^^^^^^^^^^^^^
  File "/usr/lib/python3/dist-packages/gpiozero/output_devices.py", line 121, in value
    return super().value
           ^^^^^^^^^^^^^
  File "/usr/lib/python3/dist-packages/gpiozero/devices.py", line 602, in value
    return self._read()
           ^^^^^^^^^^^^
  File "/usr/lib/python3/dist-packages/gpiozero/devices.py", line 565, in _read
    self._check_open()
  File "/usr/lib/python3/dist-packages/gpiozero/devices.py", line 587, in _check_open
    raise GPIODeviceClosed(str(e))
gpiozero.exc.GPIODeviceClosed: OutputDevice is closed or uninitialized
2025-04-16 19:33:56,733 [INFO] Starting homing procedure
2025-04-16 19:33:56,742 [INFO] Background threads started
2025-04-16 19:34:14,146 [INFO] Homing procedure complete and speed limits set
2025-04-16 19:34:14,146 [INFO] Homing complete
2025-04-16 19:40:52,146 [INFO] Starting homing procedure
2025-04-16 19:40:52,151 [INFO] Background threads started
2025-04-16 19:41:09,962 [INFO] Homing procedure complete and speed limits set
2025-04-16 19:41:09,963 [INFO] Homing complete
2025-04-16 20:15:10,408 [INFO] Starting homing procedure
2025-04-16 20:15:10,416 [INFO] Background threads started
2025-04-16 20:15:40,711 [ERROR] Error during homing_procedure
Traceback (most recent call last):
  File "/usr/lib/python3/dist-packages/gpiozero/devices.py", line 563, in _read
    return self._state_to_value(self.pin.state)
                                ^^^^^^^^^^^^^^
AttributeError: 'NoneType' object has no attribute 'state'

During handling of the above exception, another exception occurred:

Traceback (most recent call last):
  File "/usr/lib/python3/dist-packages/gpiozero/devices.py", line 584, in _check_open
    super()._check_open()
  File "/usr/lib/python3/dist-packages/gpiozero/devices.py", line 213, in _check_open
    raise DeviceClosed(
gpiozero.exc.DeviceClosed: DigitalInputDevice is closed or uninitialized

During handling of the above exception, another exception occurred:

Traceback (most recent call last):
  File "/home/berke/Desktop/PurrfectSpray/Code/motors.py", line 76, in homing_procedure
    home_motor(Motor1, hall_sensor_1, 1)
  File "/home/berke/Desktop/PurrfectSpray/Code/motors.py", line 54, in home_motor
    while read_sensor():
          ^^^^^^^^^^^^^
  File "/home/berke/Desktop/PurrfectSpray/Code/motors.py", line 36, in read_sensor
    return not hall_sensor.value
               ^^^^^^^^^^^^^^^^^
  File "/usr/lib/python3/dist-packages/gpiozero/devices.py", line 602, in value
    return self._read()
           ^^^^^^^^^^^^
  File "/usr/lib/python3/dist-packages/gpiozero/devices.py", line 565, in _read
    self._check_open()
  File "/usr/lib/python3/dist-packages/gpiozero/devices.py", line 587, in _check_open
    raise GPIODeviceClosed(str(e))
gpiozero.exc.GPIODeviceClosed: DigitalInputDevice is closed or uninitialized
2025-04-16 20:15:40,717 [INFO] Homing complete
2025-04-16 20:15:40,719 [ERROR] Error in motor_loop
Traceback (most recent call last):
  File "/usr/lib/python3/dist-packages/gpiozero/output_devices.py", line 87, in _write
    self.pin.state = self._value_to_state(value)
    ^^^^^^^^^^^^^^
AttributeError: 'NoneType' object has no attribute 'state'

During handling of the above exception, another exception occurred:

Traceback (most recent call last):
  File "/usr/lib/python3/dist-packages/gpiozero/devices.py", line 584, in _check_open
    super()._check_open()
  File "/usr/lib/python3/dist-packages/gpiozero/devices.py", line 213, in _check_open
    raise DeviceClosed(
gpiozero.exc.DeviceClosed: DigitalOutputDevice is closed or uninitialized

During handling of the above exception, another exception occurred:

Traceback (most recent call last):
  File "/home/berke/Desktop/PurrfectSpray/Code/app.py", line 239, in motor_loop
    Motor1.run()
  File "/home/berke/Desktop/PurrfectSpray/Code/AccelStepper.py", line 134, in run
    if self.run_speed():
       ^^^^^^^^^^^^^^^^
  File "/home/berke/Desktop/PurrfectSpray/Code/AccelStepper.py", line 75, in run_speed
    self.step(self._currentPos)
  File "/home/berke/Desktop/PurrfectSpray/Code/AccelStepper.py", line 180, in step
    self.step1(step)
  File "/home/berke/Desktop/PurrfectSpray/Code/AccelStepper.py", line 212, in step1
    self.set_output_pins(0b10 if self._direction else 0b00)
  File "/home/berke/Desktop/PurrfectSpray/Code/AccelStepper.py", line 203, in set_output_pins
    self._pins[i].off() if not self._pinInverted[i] else self._pins[i].on()
    ^^^^^^^^^^^^^^^^^^^
  File "/usr/lib/python3/dist-packages/gpiozero/output_devices.py", line 214, in off
    self._write(False)
  File "/usr/lib/python3/dist-packages/gpiozero/output_devices.py", line 89, in _write
    self._check_open()
  File "/usr/lib/python3/dist-packages/gpiozero/devices.py", line 587, in _check_open
    raise GPIODeviceClosed(str(e))
gpiozero.exc.GPIODeviceClosed: DigitalOutputDevice is closed or uninitialized
2025-04-16 20:15:40,878 [ERROR] Error in status_broadcast_loop
Traceback (most recent call last):
  File "/usr/lib/python3/dist-packages/gpiozero/devices.py", line 563, in _read
    return self._state_to_value(self.pin.state)
                                ^^^^^^^^^^^^^^
AttributeError: 'NoneType' object has no attribute 'state'

During handling of the above exception, another exception occurred:

Traceback (most recent call last):
  File "/usr/lib/python3/dist-packages/gpiozero/devices.py", line 584, in _check_open
    super()._check_open()
  File "/usr/lib/python3/dist-packages/gpiozero/devices.py", line 213, in _check_open
    raise DeviceClosed(
gpiozero.exc.DeviceClosed: OutputDevice is closed or uninitialized

During handling of the above exception, another exception occurred:

Traceback (most recent call last):
  File "/home/berke/Desktop/PurrfectSpray/Code/app.py", line 271, in status_broadcast_loop
    'laser': laser_pin.value,
             ^^^^^^^^^^^^^^^
  File "/usr/lib/python3/dist-packages/gpiozero/output_devices.py", line 121, in value
    return super().value
           ^^^^^^^^^^^^^
  File "/usr/lib/python3/dist-packages/gpiozero/devices.py", line 602, in value
    return self._read()
           ^^^^^^^^^^^^
  File "/usr/lib/python3/dist-packages/gpiozero/devices.py", line 565, in _read
    self._check_open()
  File "/usr/lib/python3/dist-packages/gpiozero/devices.py", line 587, in _check_open
    raise GPIODeviceClosed(str(e))
gpiozero.exc.GPIODeviceClosed: OutputDevice is closed or uninitialized
2025-04-16 20:17:17,806 [INFO] Starting homing procedure
2025-04-16 20:17:17,815 [INFO] Background threads started
2025-04-16 20:17:33,612 [INFO] Homing procedure complete and speed limits set
2025-04-16 20:17:33,612 [INFO] Homing complete
2025-04-16 20:21:08,288 [INFO] Starting homing procedure
2025-04-16 20:21:08,298 [INFO] Background threads started
2025-04-16 20:21:23,122 [INFO] Homing procedure complete and speed limits set
2025-04-16 20:21:23,123 [INFO] Homing complete
2025-04-16 20:22:20,822 [ERROR] Error in fan_loop
Traceback (most recent call last):
  File "/usr/lib/python3/dist-packages/gpiozero/output_devices.py", line 87, in _write
    self.pin.state = self._value_to_state(value)
    ^^^^^^^^^^^^^^
AttributeError: 'NoneType' object has no attribute 'state'

During handling of the above exception, another exception occurred:

Traceback (most recent call last):
  File "/usr/lib/python3/dist-packages/gpiozero/devices.py", line 584, in _check_open
    super()._check_open()
  File "/usr/lib/python3/dist-packages/gpiozero/devices.py", line 213, in _check_open
    raise DeviceClosed(
gpiozero.exc.DeviceClosed: OutputDevice is closed or uninitialized

During handling of the above exception, another exception occurred:

Traceback (most recent call last):
  File "/home/berke/Desktop/PurrfectSpray/Code/app.py", line 258, in fan_loop
    fan_pin.off()
  File "/usr/lib/python3/dist-packages/gpiozero/output_devices.py", line 102, in off
    self._write(False)
  File "/usr/lib/python3/dist-packages/gpiozero/output_devices.py", line 89, in _write
    self._check_open()
  File "/usr/lib/python3/dist-packages/gpiozero/devices.py", line 587, in _check_open
    raise GPIODeviceClosed(str(e))
gpiozero.exc.GPIODeviceClosed: OutputDevice is closed or uninitialized
2025-04-16 20:22:26,685 [INFO] Starting homing procedure
2025-04-16 20:22:26,693 [INFO] Background threads started
2025-04-16 20:22:41,715 [INFO] Homing procedure complete and speed limits set
2025-04-16 20:22:41,715 [INFO] Homing complete
2025-04-16 20:27:32,209 [INFO] Starting homing procedure
2025-04-16 20:27:32,223 [INFO] Background threads started
2025-04-16 20:27:48,548 [INFO] Homing procedure complete and speed limits set
2025-04-16 20:27:48,553 [INFO] Homing complete
2025-04-16 20:33:36,926 [ERROR] Error in status_broadcast_loop
Traceback (most recent call last):
  File "/usr/lib/python3/dist-packages/gpiozero/devices.py", line 563, in _read
    return self._state_to_value(self.pin.state)
                                ^^^^^^^^^^^^^^
AttributeError: 'NoneType' object has no attribute 'state'

During handling of the above exception, another exception occurred:

Traceback (most recent call last):
  File "/usr/lib/python3/dist-packages/gpiozero/devices.py", line 584, in _check_open
    super()._check_open()
  File "/usr/lib/python3/dist-packages/gpiozero/devices.py", line 213, in _check_open
    raise DeviceClosed(
gpiozero.exc.DeviceClosed: OutputDevice is closed or uninitialized

During handling of the above exception, another exception occurred:

Traceback (most recent call last):
  File "/home/berke/Desktop/PurrfectSpray/Code/app.py", line 271, in status_broadcast_loop
    'laser': laser_pin.value,
             ^^^^^^^^^^^^^^^
  File "/usr/lib/python3/dist-packages/gpiozero/output_devices.py", line 121, in value
    return super().value
           ^^^^^^^^^^^^^
  File "/usr/lib/python3/dist-packages/gpiozero/devices.py", line 602, in value
    return self._read()
           ^^^^^^^^^^^^
  File "/usr/lib/python3/dist-packages/gpiozero/devices.py", line 565, in _read
    self._check_open()
  File "/usr/lib/python3/dist-packages/gpiozero/devices.py", line 587, in _check_open
    raise GPIODeviceClosed(str(e))
gpiozero.exc.GPIODeviceClosed: OutputDevice is closed or uninitialized
2025-04-23 01:53:24,527 [INFO] Starting homing procedure
2025-04-23 01:53:24,533 [INFO] Background threads started
2025-04-23 01:53:29,479 [ERROR] Failed to forward WebRTC offer
Traceback (most recent call last):
  File "/usr/lib/python3/dist-packages/urllib3/connection.py", line 174, in _new_conn
    conn = connection.create_connection(
           ^^^^^^^^^^^^^^^^^^^^^^^^^^^^^
  File "/usr/lib/python3/dist-packages/urllib3/util/connection.py", line 96, in create_connection
    raise err
  File "/usr/lib/python3/dist-packages/urllib3/util/connection.py", line 86, in create_connection
    sock.connect(sa)
  File "/home/berke/yolo-env/lib/python3.11/site-packages/gevent/_socketcommon.py", line 586, in connect
    self._internal_connect(address)
  File "/home/berke/yolo-env/lib/python3.11/site-packages/gevent/_socketcommon.py", line 630, in _internal_connect
    raise _SocketError(err, strerror(err))
ConnectionRefusedError: [Errno 111] Connection refused

During handling of the above exception, another exception occurred:

Traceback (most recent call last):
  File "/usr/lib/python3/dist-packages/urllib3/connectionpool.py", line 705, in urlopen
    httplib_response = self._make_request(
                       ^^^^^^^^^^^^^^^^^^^
  File "/usr/lib/python3/dist-packages/urllib3/connectionpool.py", line 400, in _make_request
    conn.request(method, url, **httplib_request_kw)
  File "/usr/lib/python3/dist-packages/urllib3/connection.py", line 239, in request
    super(HTTPConnection, self).request(method, url, body=body, headers=headers)
  File "/usr/lib/python3.11/http/client.py", line 1282, in request
    self._send_request(method, url, body, headers, encode_chunked)
  File "/usr/lib/python3.11/http/client.py", line 1328, in _send_request
    self.endheaders(body, encode_chunked=encode_chunked)
  File "/usr/lib/python3.11/http/client.py", line 1277, in endheaders
    self._send_output(message_body, encode_chunked=encode_chunked)
  File "/usr/lib/python3.11/http/client.py", line 1037, in _send_output
    self.send(msg)
  File "/usr/lib/python3.11/http/client.py", line 975, in send
    self.connect()
  File "/usr/lib/python3/dist-packages/urllib3/connection.py", line 205, in connect
    conn = self._new_conn()
           ^^^^^^^^^^^^^^^^
  File "/usr/lib/python3/dist-packages/urllib3/connection.py", line 186, in _new_conn
    raise NewConnectionError(
urllib3.exceptions.NewConnectionError: <urllib3.connection.HTTPConnection object at 0x7fff04147c90>: Failed to establish a new connection: [Errno 111] Connection refused

During handling of the above exception, another exception occurred:

Traceback (most recent call last):
  File "/home/berke/yolo-env/lib/python3.11/site-packages/requests/adapters.py", line 667, in send
    resp = conn.urlopen(
           ^^^^^^^^^^^^^
  File "/usr/lib/python3/dist-packages/urllib3/connectionpool.py", line 789, in urlopen
    retries = retries.increment(
              ^^^^^^^^^^^^^^^^^^
  File "/usr/lib/python3/dist-packages/urllib3/util/retry.py", line 594, in increment
    raise MaxRetryError(_pool, url, error or ResponseError(cause))
urllib3.exceptions.MaxRetryError: HTTPConnectionPool(host='localhost', port=8080): Max retries exceeded with url: /offer (Caused by NewConnectionError('<urllib3.connection.HTTPConnection object at 0x7fff04147c90>: Failed to establish a new connection: [Errno 111] Connection refused'))

During handling of the above exception, another exception occurred:

Traceback (most recent call last):
  File "/home/berke/Desktop/PurrfectSpray/Code/app.py", line 52, in offer_proxy
    webrtc_res = requests.post("http://localhost:8080/offer", json=request.get_json())
                 ^^^^^^^^^^^^^^^^^^^^^^^^^^^^^^^^^^^^^^^^^^^^^^^^^^^^^^^^^^^^^^^^^^^^^
  File "/home/berke/yolo-env/lib/python3.11/site-packages/requests/api.py", line 115, in post
    return request("post", url, data=data, json=json, **kwargs)
           ^^^^^^^^^^^^^^^^^^^^^^^^^^^^^^^^^^^^^^^^^^^^^^^^^^^^
  File "/home/berke/yolo-env/lib/python3.11/site-packages/requests/api.py", line 59, in request
    return session.request(method=method, url=url, **kwargs)
           ^^^^^^^^^^^^^^^^^^^^^^^^^^^^^^^^^^^^^^^^^^^^^^^^^
  File "/home/berke/yolo-env/lib/python3.11/site-packages/requests/sessions.py", line 589, in request
    resp = self.send(prep, **send_kwargs)
           ^^^^^^^^^^^^^^^^^^^^^^^^^^^^^^
  File "/home/berke/yolo-env/lib/python3.11/site-packages/requests/sessions.py", line 703, in send
    r = adapter.send(request, **kwargs)
        ^^^^^^^^^^^^^^^^^^^^^^^^^^^^^^^
  File "/home/berke/yolo-env/lib/python3.11/site-packages/requests/adapters.py", line 700, in send
    raise ConnectionError(e, request=request)
requests.exceptions.ConnectionError: HTTPConnectionPool(host='localhost', port=8080): Max retries exceeded with url: /offer (Caused by NewConnectionError('<urllib3.connection.HTTPConnection object at 0x7fff04147c90>: Failed to establish a new connection: [Errno 111] Connection refused'))
2025-04-23 01:53:39,223 [ERROR] Error during homing_procedure
Traceback (most recent call last):
  File "/usr/lib/python3/dist-packages/gpiozero/devices.py", line 563, in _read
    return self._state_to_value(self.pin.state)
                                ^^^^^^^^^^^^^^
AttributeError: 'NoneType' object has no attribute 'state'

During handling of the above exception, another exception occurred:

Traceback (most recent call last):
  File "/usr/lib/python3/dist-packages/gpiozero/devices.py", line 584, in _check_open
    super()._check_open()
  File "/usr/lib/python3/dist-packages/gpiozero/devices.py", line 213, in _check_open
    raise DeviceClosed(
gpiozero.exc.DeviceClosed: DigitalInputDevice is closed or uninitialized

During handling of the above exception, another exception occurred:

Traceback (most recent call last):
  File "/home/berke/Desktop/PurrfectSpray/Code/motors.py", line 77, in homing_procedure
    home_motor(Motor2, hall_sensor_2, 2)
  File "/home/berke/Desktop/PurrfectSpray/Code/motors.py", line 54, in home_motor
    while read_sensor():
          ^^^^^^^^^^^^^
  File "/home/berke/Desktop/PurrfectSpray/Code/motors.py", line 36, in read_sensor
    return not hall_sensor.value
               ^^^^^^^^^^^^^^^^^
  File "/usr/lib/python3/dist-packages/gpiozero/devices.py", line 602, in value
    return self._read()
           ^^^^^^^^^^^^
  File "/usr/lib/python3/dist-packages/gpiozero/devices.py", line 565, in _read
    self._check_open()
  File "/usr/lib/python3/dist-packages/gpiozero/devices.py", line 587, in _check_open
    raise GPIODeviceClosed(str(e))
gpiozero.exc.GPIODeviceClosed: DigitalInputDevice is closed or uninitialized
2025-04-23 01:53:39,227 [INFO] Homing complete
2025-04-23 01:53:39,329 [ERROR] Error in motor_loop
Traceback (most recent call last):
  File "/usr/lib/python3/dist-packages/gpiozero/output_devices.py", line 87, in _write
    self.pin.state = self._value_to_state(value)
    ^^^^^^^^^^^^^^
AttributeError: 'NoneType' object has no attribute 'state'

During handling of the above exception, another exception occurred:

Traceback (most recent call last):
  File "/usr/lib/python3/dist-packages/gpiozero/devices.py", line 584, in _check_open
    super()._check_open()
  File "/usr/lib/python3/dist-packages/gpiozero/devices.py", line 213, in _check_open
    raise DeviceClosed(
gpiozero.exc.DeviceClosed: DigitalOutputDevice is closed or uninitialized

During handling of the above exception, another exception occurred:

Traceback (most recent call last):
  File "/home/berke/Desktop/PurrfectSpray/Code/app.py", line 271, in motor_loop
    Motor2.run()
  File "/home/berke/Desktop/PurrfectSpray/Code/AccelStepper.py", line 134, in run
    if self.run_speed():
       ^^^^^^^^^^^^^^^^
  File "/home/berke/Desktop/PurrfectSpray/Code/AccelStepper.py", line 75, in run_speed
    self.step(self._currentPos)
  File "/home/berke/Desktop/PurrfectSpray/Code/AccelStepper.py", line 180, in step
    self.step1(step)
  File "/home/berke/Desktop/PurrfectSpray/Code/AccelStepper.py", line 212, in step1
    self.set_output_pins(0b10 if self._direction else 0b00)
  File "/home/berke/Desktop/PurrfectSpray/Code/AccelStepper.py", line 203, in set_output_pins
    self._pins[i].off() if not self._pinInverted[i] else self._pins[i].on()
    ^^^^^^^^^^^^^^^^^^^
  File "/usr/lib/python3/dist-packages/gpiozero/output_devices.py", line 214, in off
    self._write(False)
  File "/usr/lib/python3/dist-packages/gpiozero/output_devices.py", line 89, in _write
    self._check_open()
  File "/usr/lib/python3/dist-packages/gpiozero/devices.py", line 587, in _check_open
    raise GPIODeviceClosed(str(e))
gpiozero.exc.GPIODeviceClosed: DigitalOutputDevice is closed or uninitialized
2025-04-23 01:54:44,230 [INFO] Starting homing procedure
2025-04-23 01:54:44,245 [INFO] Background threads started
2025-04-23 01:55:00,732 [INFO] Homing procedure complete and speed limits set
2025-04-23 01:55:00,733 [INFO] Homing complete
